Workbook

Sheet Base_Insumos
A1: Chave | B1: Regiao | C1: Empresa | D1: Desc_Empresa | E1: Safra | F1: Modulo | G1: Codigo | H1: Fazenda | I1: Zona | J1: Talhao | K1: CCusto | L1: Cd_Custo | M1: Cod Operacao | N1: Desc Operacao | O1: Cod Tipo Propr | P1: Descr Tipo Propr | Q1: Tipo Propr | R1: Grupo Insumo | S1: Descr Grupo Insumo | T1: Cod Insumo | U1: Descr Insumo | V1: Data Aplicacao | W1: Área | X1: Qtde Insumo | Y1: Medida | Z1: Dosagem | AA1: Área_Talhao | AB1: instancia
A2: 90030100002 | B2: 4-Assis | C2: 61 | D2: Assis | E2: 22627 | F2: 0071 | G2: 9003 | H2: FAZENDA SANTA ROSA | I2: 10 | J2: 2 | K2: 3620 | L2: 3620 | M2: 167 | N2: Aplicação de Calcario | O2: 1 | P2: PROP.T. PROPRIA -PJ | Q2: P | R2: 1 | S2: Corretivos | T2: 3502934 | U2: CALCARIO DOLOMITICO PRNT80% | V2: 46079 | W2: 4.42 | X2: 4.33337 | Y2: T | Z2: 0.98 | AA2: 6.96 | AB2: Ipaussu
A3: 90030100003 | B3: 4-Assis | C3: 61 | D3: Assis | E3: 22627 | F3: 0071 | G3: 9003 | H3: FAZENDA SANTA ROSA | I3: 10 | J3: 3 | K3: 3620 | L3: 3620 | M3: 167 | N3: Aplicação de Calcario | O3: 1 | P3: PROP.T. PROPRIA -PJ | Q3: P | R3: 1 | S3: Corretivos | T3: 3502934 | U3: CALCARIO DOLOMITICO PRNT80% | V3: 46079 | W3: 0.5 | X3: 0.4902 | Y3: T | Z3: 0.98 | AA3: 2.28 | AB3: Ipaussu
A4: 90030100004 | B4: 4-Assis | C4: 61 | D4: Assis | E4: 22627 | F4: 0071 | G4: 9003 | H4: FAZENDA SANTA ROSA | I4: 10 | J4: 4 | K4: 3620 | L4: 3620 | M4: 167 | N4: Aplicação de Calcario | O4: 1 | P4: PROP.T. PROPRIA -PJ | Q4: P | R4: 1 | S4: Corretivos | T4: 3502934 | U4: CALCARIO DOLOMITICO PRNT80% | V4: 46079 | W4: 1 | X4: 0.9804 | Y4: T | Z4: 0.98 | AA4: 2.3 | AB4: Ipaussu
A5: 90030100006 | B5: 4-Assis | C5: 61 | D5: Assis | E5: 22627 | F5: 0071 | G5: 9003 | H5: FAZENDA SANTA ROSA | I5: 10 | J5: 6 | K5: 3620 | L5: 3620 | M5: 167 | N5: Aplicação de Calcario | O5: 1 | P5: PROP.T. PROPRIA -PJ | Q5: P | R5: 1 | S5: Corretivos | T5: 3502934 | U5: CALCARIO DOLOMITICO PRNT80% | V5: 46079 | W5: 0.83 | X5: 0.81373 | Y5: T | Z5: 0.98 | AA5: 3.17 | AB5: Ipaussu
A6: 90030100007 | B6: 4-Assis | C6: 61 | D6: Assis | E6: 22627 | F6: 0071 | G6: 9003 | H6: FAZENDA SANTA ROSA | I6: 10 | J6: 7 | K6: 3620 | L6: 3620 | M6: 167 | N6: Aplicação de Calcario | O6: 1 | P6: PROP.T. PROPRIA -PJ | Q6: P | R6: 1 | S6: Corretivos | T6: 3502934 | U6: CALCARIO DOLOMITICO PRNT80% | V6: 46079 | W6: 0.64 | X6: 0.62746 | Y6: T | Z6: 0.98 | AA6: 3.52 | AB6: Ipaussu
A7: 90030100008 | B7: 4-Assis | C7: 61 | D7: Assis | E7: 22627 | F7: 0071 | G7: 9003 | H7: FAZENDA SANTA ROSA | I7: 10 | J7: 8 | K7: 3620 | L7: 3620 | M7: 167 | N7: Aplicação de Calcario | O7: 1 | P7: PROP.T. PROPRIA -PJ | Q7: P | R7: 1 | S7: Corretivos | T7: 3502934 | U7: CALCARIO DOLOMITICO PRNT80% | V7: 46079 | W7: 0.77 | X7: 0.75491 | Y7: T | Z7: 0.98 | AA7: 4.33 | AB7: Ipaussu
A8: 91251280001 | B8: 4-Assis | C8: 61 | D8: Assis | E8: 22728 | F8: 0071 | G8: 9125 | H8: FAZ.SANTA CECILIA GLEBA A | I8: 128 | J8: 1 | K8: 3620 | L8: 3620 | M8: 167 | N8: Aplicação de Calcario | O8: 2 | P8: PROP.T. ARREND. PJ | Q8: P | R8: 1 | S8: Corretivos | T8: 3502934 | U8: CALCARIO DOLOMITICO PRNT80% | V8: 46048 | W8: 3.78 | X8: 3.63447 | Y8: T | Z8: 0.962 | AA8: 3.78 | AB8: Ipaussu
A9: 91251280002 | B9: 4-Assis | C9: 61 | D9: Assis | E9: 22728 | F9: 0071 | G9: 9125 | H9: FAZ.SANTA CECILIA GLEBA A | I9: 128 | J9: 2 | K9: 3620 | L9: 3620 | M9: 167 | N9: Aplicação de Calcario | O9: 2 | P9: PROP.T. ARREND. PJ | Q9: P | R9: 1 | S9: Corretivos | T9: 3502934 | U9: CALCARIO DOLOMITICO PRNT80% | V9: 46048 | W9: 2.31 | X9: 2.22107 | Y9: T | Z9: 0.962 | AA9: 2.31 | AB9: Ipaussu
A10: 91251280003 | B10: 4-Assis | C10: 61 | D10: Assis | E10: 22728 | F10: 0071 | G10: 9125 | H10: FAZ.SANTA CECILIA GLEBA A | I10: 128 | J10: 3 | K10: 3620 | L10: 3620 | M10: 167 | N10: Aplicação de Calcario | O10: 2 | P10: PROP.T. ARREND. PJ | Q10: P | R10: 1 | S10: Corretivos | T10: 3502934 | U10: CALCARIO DOLOMITICO PRNT80% | V10: 46048 | W10: 2.8 | X10: 2.6922 | Y10: T | Z10: 0.962 | AA10: 2.8 | AB10: Ipaussu
A11: 91251280004 | B11: 4-Assis | C11: 61 | D11: Assis | E11: 22728 | F11: 0071 | G11: 9125 | H11: FAZ.SANTA CECILIA GLEBA A | I11: 128 | J11: 4 | K11: 3620 | L11: 3620 | M11: 167 | N11: Aplicação de Calcario | O11: 2 | P11: PROP.T. ARREND. PJ | Q11: P | R11: 1 | S11: Corretivos | T11: 3502934 | U11: CALCARIO DOLOMITICO PRNT80% | V11: 46048 | W11: 0.23 | X11: 0.22115 | Y11: T | Z11: 0.962 | AA11: 0.23 | AB11: Ipaussu
A12: 91251280005 | B12: 4-Assis | C12: 61 | D12: Assis | E12: 22728 | F12: 0071 | G12: 9125 | H12: FAZ.SANTA CECILIA GLEBA A | I12: 128 | J12: 5 | K12: 3620 | L12: 3620 | M12: 167 | N12: Aplicação de Calcario | O12: 2 | P12: PROP.T. ARREND. PJ | Q12: P | R12: 1 | S12: Corretivos | T12: 3502934 | U12: CALCARIO DOLOMITICO PRNT80% | V12: 46048 | W12: 0.08 | X12: 0.07692 | Y12: T | Z12: 0.962 | AA12: 0.08 | AB12: Ipaussu
A13: 91251280006 | B13: 4-Assis | C13: 61 | D13: Assis | E13: 22728 | F13: 0071 | G13: 9125 | H13: FAZ.SANTA CECILIA GLEBA A | I13: 128 | J13: 6 | K13: 3620 | L13: 3620 | M13: 167 | N13: Aplicação de Calcario | O13: 2 | P13: PROP.T. ARREND. PJ | Q13: P | R13: 1 | S13: Corretivos | T13: 3502934 | U13: CALCARIO DOLOMITICO PRNT80% | V13: 46048 | W13: 0.16 | X13: 0.15384 | Y13: T | Z13: 0.962 | AA13: 0.16 | AB13: Ipaussu
... A142: 764667960036 | B142: 4-Assis | C142: 61 | D142: Assis | E142: 22627 | F142: 0071 | G142: 76466 | H142: FAZENDA SANTA MARIA | I142: 796 | J142: 36 | K142: 3620 | L142: 3620 | M142: 1007 | N142: Aplicação Calcario Caminh | O142: 2 | P142: PROP.T. ARREND. PJ | Q142: P | R142: 1 | S142: Corretivos | T142: 3502934 | U142: CALCARIO DOLOMITICO PRNT80% | V142: 46051 | W142: 1 | X142: 1.1917 | Y142: T | Z142: 1.192 | AA142: 1.9 | AB142: Ipaussu

Sheet Base Notas 
B1: Controle de Insumo (Corretivo) | N1: Legenda
N2: P01 | O2: Patio Santa Rosa
N3: P02 | O3: Patio Esplanada
N4: P03 | O4: Niagara
A5: Chavessig | B5: NF/saida | C5: Data | D5: Fazenda | E5: Descrição Fazenda | F5: Zona | G5: Insumo | H5: Peso | I5: Status | J5: Mês | K5: NF Entregues ao almoxarifado ? | L5: Observação
A6: =D6&F6 -> 19301283 | B6: 409826 | D6: 19301 | E6: =VLOOKUP(Tabela1[[#This Row],[Fazenda ]],'Base Fazendas'!A:B,2,0) -> SAO PAULO | F6: 283 | G6: Calcario | H6: 33.13 | I6: 46087 | J6: =TEXT(Tabela1[[#This Row],[Status ]],"mmmm") -> março | K6: Sim
A7: =D7&F7 -> 19301283 | B7: 409834 | D7: 19301 | E7: =VLOOKUP(Tabela1[[#This Row],[Fazenda ]],'Base Fazendas'!A:B,2,0) -> SAO PAULO | F7: 283 | G7: Calcario | H7: 34.66 | I7: 46087 | J7: =TEXT(Tabela1[[#This Row],[Status ]],"mmmm") -> março | K7: Sim
A8: =D8&F8 -> 19301281 | B8: 409905 | D8: 19301 | E8: =VLOOKUP(Tabela1[[#This Row],[Fazenda ]],'Base Fazendas'!A:B,2,0) -> SAO PAULO | F8: 281 | G8: Calcario | H8: 38.86 | I8: 46088 | J8: =TEXT(Tabela1[[#This Row],[Status ]],"mmmm") -> março | K8: Sim
A9: =D9&F9 -> 19301281 | B9: 409873 | D9: 19301 | E9: =VLOOKUP(Tabela1[[#This Row],[Fazenda ]],'Base Fazendas'!A:B,2,0) -> SAO PAULO | F9: 281 | G9: Calcario | H9: 33.64 | I9: 46088 | J9: =TEXT(Tabela1[[#This Row],[Status ]],"mmmm") -> março | K9: Sim
A10: =D10&F10 -> 19301281 | B10: 409908 | D10: 19301 | E10: =VLOOKUP(Tabela1[[#This Row],[Fazenda ]],'Base Fazendas'!A:B,2,0) -> SAO PAULO | F10: 281 | G10: Calcario | H10: 30.86 | I10: 46088 | J10: =TEXT(Tabela1[[#This Row],[Status ]],"mmmm") -> março | K10: Sim
A11: =D11&F11 -> 19301283 | B11: 409831 | D11: 19301 | E11: =VLOOKUP(Tabela1[[#This Row],[Fazenda ]],'Base Fazendas'!A:B,2,0) -> SAO PAULO | F11: 283 | G11: Calcario | H11: 40.95 | I11: 46088 | J11: =TEXT(Tabela1[[#This Row],[Status ]],"mmmm") -> março | K11: Sim
A12: =D12&F12 -> 19301283 | B12: 409942 | D12: 19301 | E12: =VLOOKUP(Tabela1[[#This Row],[Fazenda ]],'Base Fazendas'!A:B,2,0) -> SAO PAULO | F12: 283 | G12: Calcario | H12: 41.75 | I12: 46090 | J12: =TEXT(Tabela1[[#This Row],[Status ]],"mmmm") -> março | K12: Sim
A13: =D13&F13 -> p021 | B13: 409940 | D13: p02 | E13: =VLOOKUP(Tabela1[[#This Row],[Fazenda ]],'Base Fazendas'!A:B,2,0) -> Patio Esplanada | F13: 1 | G13: Calcario | H13: 39.78 | I13: 46090 | J13: =TEXT(Tabela1[[#This Row],[Status ]],"mmmm") -> março | K13: Sim
A14: =D14&F14 -> p021 | B14: 409931 | D14: p02 | E14: =VLOOKUP(Tabela1[[#This Row],[Fazenda ]],'Base Fazendas'!A:B,2,0) -> Patio Esplanada | F14: 1 | G14: Calcario | H14: 32.17 | I14: 46090 | J14: =TEXT(Tabela1[[#This Row],[Status ]],"mmmm") -> março | K14: Sim
A15: =D15&F15 -> p021 | B15: 409919 | D15: p02 | E15: =VLOOKUP(Tabela1[[#This Row],[Fazenda ]],'Base Fazendas'!A:B,2,0) -> Patio Esplanada | F15: 1 | G15: Calcario | H15: 32.53 | I15: 46090 | J15: =TEXT(Tabela1[[#This Row],[Status ]],"mmmm") -> março | K15: Sim
A16: =D16&F16 -> 19301283 | B16: 410385 | D16: 19301 | E16: =VLOOKUP(Tabela1[[#This Row],[Fazenda ]],'Base Fazendas'!A:B,2,0) -> SAO PAULO | F16: 283 | G16: Calcario | H16: 43.44 | I16: 46099 | J16: =TEXT(Tabela1[[#This Row],[Status ]],"mmmm") -> março | K16: Sim
A17: =D17&F17 -> p021 | B17: 410465 | D17: p02 | E17: =VLOOKUP(Tabela1[[#This Row],[Fazenda ]],'Base Fazendas'!A:B,2,0) -> Patio Esplanada | F17: 1 | G17: Calcario | H17: 40.58 | I17: 46100 | J17: =TEXT(Tabela1[[#This Row],[Status ]],"mmmm") -> março | K17: Sim
A18: =D18&F18 -> 19301283 | B18: 410380 | D18: 19301 | E18: =VLOOKUP(Tabela1[[#This Row],[Fazenda ]],'Base Fazendas'!A:B,2,0) -> SAO PAULO | F18: 283 | G18: Calcario | H18: 42.48 | I18: 46101 | J18: =TEXT(Tabela1[[#This Row],[Status ]],"mmmm") -> março | K18: Sim
A19: =D19&F19 -> 19301282 | B19: 411012 | D19: 19301 | E19: =VLOOKUP(Tabela1[[#This Row],[Fazenda ]],'Base Fazendas'!A:B,2,0) -> SAO PAULO | F19: 282 | G19: Calcario | H19: 31.03 | I19: 46109 | J19: =TEXT(Tabela1[[#This Row],[Status ]],"mmmm") -> março | K19: Sim
A20: =D20&F20 -> 19301282 | B20: 411014 | D20: 19301 | E20: =VLOOKUP(Tabela1[[#This Row],[Fazenda ]],'Base Fazendas'!A:B,2,0) -> SAO PAULO | F20: 282 | G20: Calcario | H20: 31.47 | I20: 46109 | J20: =TEXT(Tabela1[[#This Row],[Status ]],"mmmm") -> março | K20: Sim
A21: =D21&F21 -> p021 | B21: 412084 | D21: p02 | E21: =VLOOKUP(Tabela1[[#This Row],[Fazenda ]],'Base Fazendas'!A:B,2,0) -> Patio Esplanada | F21: 1 | G21: Calcario | H21: 47.99 | I21: 46121 | J21: =TEXT(Tabela1[[#This Row],[Status ]],"mmmm") -> abril | K21: Sim
A22: =D22&F22 -> p021 | B22: 412090 | D22: p02 | E22: =VLOOKUP(Tabela1[[#This Row],[Fazenda ]],'Base Fazendas'!A:B,2,0) -> Patio Esplanada | F22: 1 | G22: Calcario | H22: 50.51 | I22: 46121 | J22: =TEXT(Tabela1[[#This Row],[Status ]],"mmmm") -> abril | K22: Sim
A23: =D23&F23 -> p021 | B23: 412102 | D23: p02 | E23: =VLOOKUP(Tabela1[[#This Row],[Fazenda ]],'Base Fazendas'!A:B,2,0) -> Patio Esplanada | F23: 1 | G23: Calcario | H23: 48.11 | I23: 46121 | J23: =TEXT(Tabela1[[#This Row],[Status ]],"mmmm") -> abril | K23: Sim
A24: =D24&F24 -> p021 | B24: 412103 | D24: p02 | E24: =VLOOKUP(Tabela1[[#This Row],[Fazenda ]],'Base Fazendas'!A:B,2,0) -> Patio Esplanada | F24: 1 | G24: Calcario | H24: 47.1 | I24: 46121 | J24: =TEXT(Tabela1[[#This Row],[Status ]],"mmmm") -> abril | K24: Sim
A25: =D25&F25 -> p021 | B25: 412092 | D25: p02 | E25: =VLOOKUP(Tabela1[[#This Row],[Fazenda ]],'Base Fazendas'!A:B,2,0) -> Patio Esplanada | F25: 1 | G25: Calcario | H25: 50.38 | I25: 46121 | J25: =TEXT(Tabela1[[#This Row],[Status ]],"mmmm") -> abril | K25: Sim
A26: =D26&F26 -> 19301282 | B26: 412204 | D26: 19301 | E26: =VLOOKUP(Tabela1[[#This Row],[Fazenda ]],'Base Fazendas'!A:B,2,0) -> SAO PAULO | F26: 282 | G26: Calcario | H26: 45.86 | I26: 46122 | J26: =TEXT(Tabela1[[#This Row],[Status ]],"mmmm") -> abril | K26: Sim
A27: =D27&F27 -> 19301282 | B27: 412203 | D27: 19301 | E27: =VLOOKUP(Tabela1[[#This Row],[Fazenda ]],'Base Fazendas'!A:B,2,0) -> SAO PAULO | F27: 282 | G27: Calcario | H27: 46.42 | I27: 46122 | J27: =TEXT(Tabela1[[#This Row],[Status ]],"mmmm") -> abril | K27: Sim
A28: =D28&F28 -> 19301282 | B28: 412193 | D28: 19301 | E28: =VLOOKUP(Tabela1[[#This Row],[Fazenda ]],'Base Fazendas'!A:B,2,0) -> SAO PAULO | F28: 282 | G28: Calcario | H28: 46.06 | I28: 46122 | J28: =TEXT(Tabela1[[#This Row],[Status ]],"mmmm") -> abril | K28: Sim
A29: =D29&F29 -> 19301282 | B29: 412182 | D29: 19301 | E29: =VLOOKUP(Tabela1[[#This Row],[Fazenda ]],'Base Fazendas'!A:B,2,0) -> SAO PAULO | F29: 282 | G29: Calcario | H29: 46.99 | I29: 46122 | J29: =TEXT(Tabela1[[#This Row],[Status ]],"mmmm") -> abril | K29: Sim
A30: =D30&F30 -> 19301282 | B30: 412192 | D30: 19301 | E30: =VLOOKUP(Tabela1[[#This Row],[Fazenda ]],'Base Fazendas'!A:B,2,0) -> SAO PAULO | F30: 282 | G30: Calcario | H30: 46.08 | I30: 46122 | J30: =TEXT(Tabela1[[#This Row],[Status ]],"mmmm") -> abril | K30: Sim
A31: =D31&F31 -> 19301282 | B31: 412174 | D31: 19301 | E31: =VLOOKUP(Tabela1[[#This Row],[Fazenda ]],'Base Fazendas'!A:B,2,0) -> SAO PAULO | F31: 282 | G31: Calcario | H31: 47.84 | I31: 46122 | J31: =TEXT(Tabela1[[#This Row],[Status ]],"mmmm") -> abril | K31: Sim
A32: =D32&F32 -> 19301282 | B32: 412217 | D32: 19301 | E32: =VLOOKUP(Tabela1[[#This Row],[Fazenda ]],'Base Fazendas'!A:B,2,0) -> SAO PAULO | F32: 282 | G32: Calcario | H32: 41.59 | I32: 46122 | J32: =TEXT(Tabela1[[#This Row],[Status ]],"mmmm") -> abril | K32: Sim
A33: =D33&F33 | E33: =VLOOKUP(Tabela1[[#This Row],[Fazenda ]],'Base Fazendas'!A:B,2,0) -> #N/A
A34: =D34&F34 | E34: =VLOOKUP(Tabela1[[#This Row],[Fazenda ]],'Base Fazendas'!A:B,2,0) -> #N/A
A35: =D35&F35 | E35: =VLOOKUP(Tabela1[[#This Row],[Fazenda ]],'Base Fazendas'!A:B,2,0) -> #N/A
A36: =D36&F36 | E36: =VLOOKUP(Tabela1[[#This Row],[Fazenda ]],'Base Fazendas'!A:B,2,0) -> #N/A
A37: =D37&F37 | E37: =VLOOKUP(Tabela1[[#This Row],[Fazenda ]],'Base Fazendas'!A:B,2,0) -> #N/A
A38: =D38&F38 | E38: =VLOOKUP(Tabela1[[#This Row],[Fazenda ]],'Base Fazendas'!A:B,2,0) -> #N/A
A39: =D39&F39 | E39: =VLOOKUP(Tabela1[[#This Row],[Fazenda ]],'Base Fazendas'!A:B,2,0) -> #N/A
A40: =D40&F40 | E40: =VLOOKUP(Tabela1[[#This Row],[Fazenda ]],'Base Fazendas'!A:B,2,0) -> #N/A
...

Sheet Planilha2
A3: Rótulos de Linha | B3: Soma de Peso
A4: semana 2 | B4: 146.23
A5: semana 3 | B5: 126.5
A6: semana1 | B6: 212.1
A7: semanda 4 | B7: 62.5
A8: Total Geral | B8: 547.33

Sheet Planilha3
A3: Rótulos de Linha | B3: Soma de Peso
A4: 46087 | B4: 67.79
A5: 46088 | B5: 144.31
A6: 46090 | B6: 146.23
A7: 46099 | B7: 43.44
A8: 46100 | B8: 40.58
A9: 46101 | B9: 42.48
A10: 46109 | B10: 62.5
A11: Total Geral | B11: 547.33

Sheet Planilha1
A1: Insumo | B1: Peso | C1: Status | D1: Semana
A2: Calcario | B2: 33.13 | C2: 46087 | D2: semana1
A3: Calcario | B3: 34.66 | C3: 46087 | D3: semana1
A4: Calcario | B4: 38.86 | C4: 46088 | D4: semana1
A5: Calcario | B5: 33.64 | C5: 46088 | D5: semana1
A6: Calcario | B6: 30.86 | C6: 46088 | D6: semana1
A7: Calcario | B7: 40.95 | C7: 46088 | D7: semana1
A8: Calcario | B8: 41.75 | C8: 46090 | D8: semana 2
A9: Calcario | B9: 39.78 | C9: 46090 | D9: semana 2
A10: Calcario | B10: 32.17 | C10: 46090 | D10: semana 2
A11: Calcario | B11: 32.53 | C11: 46090 | D11: semana 2
A12: Calcario | B12: 43.44 | C12: 46099 | D12: semana 3
A13: Calcario | B13: 40.58 | C13: 46100 | D13: semana 3
... A16: Calcario | B16: 31.47 | C16: 46109 | D16: semanda 4

Sheet Estoque 
A1: CONTROLE ESTOQUE DE CORRETIVO SF 25'26 | T1: Entrega total | U1: Apontado | V1: Saldo fisico | W1: Saldo almoxarifado | X1: Dif | Y1: Entrega total | Z1: Apontado | AA1: Saldo fisico | AB1: Saldo almoxarifado | AC1: Dif
T2: Calcario | Y2: Gesso
T3: =SUM(H6:H481) -> 1112.26 | U3: =SUM(L6:L478) -> #REF! | V3: =T3-U3 -> #REF! | W3: 3548 | X3: =V3-W3 -> #REF! | Y3: =SUM(I6:I481) -> 0 | Z3: =SUM(M6:M481) -> #REF! | AA3: =Y3-Z3 -> #REF! | AB3: 1051 | AC3: =AA3-AB3 -> #REF!
A4: Dados da Fazenda eou Patio | E4: Recomendação | G4: Taxa | H4: Estoque (Entrada NF) | J4: DIFERENÇA TRANSPORTE | L4: Apontamento (Saída NF) | N4: Diferença Patio | P4: Aderencia Final | R4: Justificativa
A5: Chavesig | B5: Cód. | C5: Descrição Fazenda | D5: Zona | E5: Calcario | F5: Gesso | G5: Taxa | H5: Calcario | I5: Gesso | J5: CALCARIO | K5: Gesso | L5: Calcario | M5: Gesso | N5: Calcario | O5: Gesso | P5: Calcario | Q5: Gesso | R5: Calcario | S5: Gesso
A6: =B6&D6 -> P031 | B6: P03 | C6: Niagara | D6: 1 | E6: =SUMIFS(Tratos!#REF!,Tratos!#REF!,'Estoque '!A6,Tratos!#REF!,'Estoque '!$E$5) -> #REF! | F6: =SUMIFS(Tratos!#REF!,Tratos!#REF!,'Estoque '!A6,Tratos!#REF!,'Estoque '!$F$5) -> #REF! | G6: =VLOOKUP(A6,Tratos!#REF!,7,0) -> #REF! | H6: =SUMIFS('Base Notas '!$H:$H,'Base Notas '!$A:$A,'Estoque '!A6,'Base Notas '!$G:$G,'Estoque '!$H$5) -> 0 | I6: =SUMIFS('Base Notas '!$H:$H,'Base Notas '!$A:$A,'Estoque '!A6,'Base Notas '!$G:$G,'Estoque '!$I$5) -> 0 | J6: =H6-E6 -> #REF! | K6: =I6-F6 -> #REF! | L6: =SUMIFS(#REF!,#REF!,'Estoque '!$L$5,#REF!,'Estoque '!A6) -> #REF! | M6: =SUMIFS(#REF!,#REF!,'Estoque '!$M$5,#REF!,'Estoque '!A6) -> #REF! | N6: =H6-L6 -> #REF! | O6: =I6-M6 -> #REF! | P6: =IFERROR(E6/L6-1,"") | Q6: =IFERROR(I6/M6-1,"")
A7: =B7&D7 -> P021 | B7: P02 | C7: Patio Esplanada | D7: 1 | E7: =SUMIFS(Tratos!#REF!,Tratos!#REF!,'Estoque '!A7,Tratos!#REF!,'Estoque '!$E$5) -> #REF! | F7: =SUMIFS(Tratos!#REF!,Tratos!#REF!,'Estoque '!A7,Tratos!#REF!,'Estoque '!$F$5) -> #REF! | G7: =VLOOKUP(A7,Tratos!#REF!,7,0) -> #REF! | H7: =SUMIFS('Base Notas '!$H:$H,'Base Notas '!$A:$A,'Estoque '!A7,'Base Notas '!$G:$G,'Estoque '!$H$5) -> 389.15 | I7: =SUMIFS('Base Notas '!$H:$H,'Base Notas '!$A:$A,'Estoque '!A7,'Base Notas '!$G:$G,'Estoque '!$I$5) -> 0 | J7: =H7-E7 -> #REF! | K7: =I7-F7 -> #REF! | L7: =SUMIFS(#REF!,#REF!,'Estoque '!$L$5,#REF!,'Estoque '!A7) -> #REF! | M7: =SUMIFS(#REF!,#REF!,'Estoque '!$M$5,#REF!,'Estoque '!A7) -> #REF! | N7: P01 | O7: 1 | P7: =IFERROR(E7/L7-1,"") | Q7: =IFERROR(I7/M7-1,"")
A8: =B8&D8 -> P011 | B8: P01 | C8: Patio Santa Rosa | D8: 1 | E8: =SUMIFS(Tratos!#REF!,Tratos!#REF!,'Estoque '!A8,Tratos!#REF!,'Estoque '!$E$5) -> #REF! | F8: =SUMIFS(Tratos!#REF!,Tratos!#REF!,'Estoque '!A8,Tratos!#REF!,'Estoque '!$F$5) -> #REF! | G8: =VLOOKUP(A8,Tratos!#REF!,7,0) -> #REF! | H8: =SUMIFS('Base Notas '!$H:$H,'Base Notas '!$A:$A,'Estoque '!A8,'Base Notas '!$G:$G,'Estoque '!$H$5) -> 0 | I8: =SUMIFS('Base Notas '!$H:$H,'Base Notas '!$A:$A,'Estoque '!A8,'Base Notas '!$G:$G,'Estoque '!$I$5) -> 0 | J8: =H8-E8 -> #REF! | K8: =I8-F8 -> #REF! | L8: =SUMIFS(#REF!,#REF!,'Estoque '!$L$5,#REF!,'Estoque '!A8) -> #REF! | M8: =SUMIFS(#REF!,#REF!,'Estoque '!$M$5,#REF!,'Estoque '!A8) -> #REF! | N8: =H8-L8 -> #REF! | O8: =I8-M8 -> #REF! | P8: =IFERROR(E8/L8-1,"") | Q8: =IFERROR(I8/M8-1,"")
A9: =B9&D9 -> 99014302 | B9: 99014 | C9: FAZENDA FAZENDINHA | D9: 302 | E9: =SUMIFS(Tratos!#REF!,Tratos!#REF!,'Estoque '!A9,Tratos!#REF!,'Estoque '!$E$5) -> #REF! | F9: =SUMIFS(Tratos!#REF!,Tratos!#REF!,'Estoque '!A9,Tratos!#REF!,'Estoque '!$F$5) -> #REF! | G9: =VLOOKUP(A9,Tratos!#REF!,7,0) -> #REF! | H9: =SUMIFS('Base Notas '!$H:$H,'Base Notas '!$A:$A,'Estoque '!A9,'Base Notas '!$G:$G,'Estoque '!$H$5) -> 0 | I9: =SUMIFS('Base Notas '!$H:$H,'Base Notas '!$A:$A,'Estoque '!A9,'Base Notas '!$G:$G,'Estoque '!$I$5) -> 0 | J9: =H9-E9 -> #REF! | K9: =I9-F9 -> #REF! | L9: =SUMIFS(#REF!,#REF!,'Estoque '!$L$5,#REF!,'Estoque '!A9) -> #REF! | M9: =SUMIFS(#REF!,#REF!,'Estoque '!$M$5,#REF!,'Estoque '!A9) -> #REF! | N9: =H9-L9 -> #REF! | O9: =I9-M9 -> #REF! | P9: =IFERROR(E9/L9-1,"") | Q9: =IFERROR(I9/M9-1,"")
A10: =B10&D10 -> 99014319 | B10: 99014 | C10: FAZENDA FAZENDINHA | D10: 319 | E10: =SUMIFS(Tratos!#REF!,Tratos!#REF!,'Estoque '!A10,Tratos!#REF!,'Estoque '!$E$5) -> #REF! | F10: =SUMIFS(Tratos!#REF!,Tratos!#REF!,'Estoque '!A10,Tratos!#REF!,'Estoque '!$F$5) -> #REF! | G10: =VLOOKUP(A10,Tratos!#REF!,7,0) -> #REF! | H10: =SUMIFS('Base Notas '!$H:$H,'Base Notas '!$A:$A,'Estoque '!A10,'Base Notas '!$G:$G,'Estoque '!$H$5) -> 0 | I10: =SUMIFS('Base Notas '!$H:$H,'Base Notas '!$A:$A,'Estoque '!A10,'Base Notas '!$G:$G,'Estoque '!$I$5) -> 0 | J10: =H10-E10 -> #REF! | K10: =I10-F10 -> #REF! | L10: =SUMIFS(#REF!,#REF!,'Estoque '!$L$5,#REF!,'Estoque '!A10) -> #REF! | M10: =SUMIFS(#REF!,#REF!,'Estoque '!$M$5,#REF!,'Estoque '!A10) -> #REF! | N10: =H10-L10 -> #REF! | O10: =I10-M10 -> #REF! | P10: =IFERROR(E10/L10-1,"") | Q10: =IFERROR(I10/M10-1,"")
A11: =B11&D11 -> 99008525 | B11: 99008 | C11: FAZENDA MADRE CABRINI I | D11: 525 | E11: =SUMIFS(Tratos!#REF!,Tratos!#REF!,'Estoque '!A11,Tratos!#REF!,'Estoque '!$E$5) -> #REF! | F11: =SUMIFS(Tratos!#REF!,Tratos!#REF!,'Estoque '!A11,Tratos!#REF!,'Estoque '!$F$5) -> #REF! | G11: =VLOOKUP(A11,Tratos!#REF!,7,0) -> #REF! | H11: =SUMIFS('Base Notas '!$H:$H,'Base Notas '!$A:$A,'Estoque '!A11,'Base Notas '!$G:$G,'Estoque '!$H$5) -> 0 | I11: =SUMIFS('Base Notas '!$H:$H,'Base Notas '!$A:$A,'Estoque '!A11,'Base Notas '!$G:$G,'Estoque '!$I$5) -> 0 | J11: =H11-E11 -> #REF! | K11: =I11-F11 -> #REF! | L11: =SUMIFS(#REF!,#REF!,'Estoque '!$L$5,#REF!,'Estoque '!A11) -> #REF! | M11: =SUMIFS(#REF!,#REF!,'Estoque '!$M$5,#REF!,'Estoque '!A11) -> #REF! | N11: =H11-L11 -> #REF! | O11: =I11-M11 -> #REF! | P11: =IFERROR(E11/L11-1,"") | Q11: =IFERROR(I11/M11-1,"")
A12: =B12&D12 -> 99008524 | B12: 99008 | C12: FAZENDA MADRE CABRINI I | D12: 524 | E12: =SUMIFS(Tratos!#REF!,Tratos!#REF!,'Estoque '!A12,Tratos!#REF!,'Estoque '!$E$5) -> #REF! | F12: =SUMIFS(Tratos!#REF!,Tratos!#REF!,'Estoque '!A12,Tratos!#REF!,'Estoque '!$F$5) -> #REF! | G12: =VLOOKUP(A12,Tratos!#REF!,7,0) -> #REF! | H12: =SUMIFS('Base Notas '!$H:$H,'Base Notas '!$A:$A,'Estoque '!A12,'Base Notas '!$G:$G,'Estoque '!$H$5) -> 0 | I12: =SUMIFS('Base Notas '!$H:$H,'Base Notas '!$A:$A,'Estoque '!A12,'Base Notas '!$G:$G,'Estoque '!$I$5) -> 0 | J12: =H12-E12 -> #REF! | K12: =I12-F12 -> #REF! | L12: =SUMIFS(#REF!,#REF!,'Estoque '!$L$5,#REF!,'Estoque '!A12) -> #REF! | M12: =SUMIFS(#REF!,#REF!,'Estoque '!$M$5,#REF!,'Estoque '!A12) -> #REF! | N12: =H12-L12 -> #REF! | O12: =I12-M12 -> #REF! | P12: =IFERROR(E12/L12-1,"") | Q12: =IFERROR(I12/M12-1,"")
A13: =B13&D13 -> 98883484 | B13: 98883 | C13: FAZENDA SANTA ROSA DE LIMA | D13: 484 | E13: =SUMIFS(Tratos!#REF!,Tratos!#REF!,'Estoque '!A13,Tratos!#REF!,'Estoque '!$E$5) -> #REF! | F13: =SUMIFS(Tratos!#REF!,Tratos!#REF!,'Estoque '!A13,Tratos!#REF!,'Estoque '!$F$5) -> #REF! | G13: =VLOOKUP(A13,Tratos!#REF!,7,0) -> #REF! | H13: =SUMIFS('Base Notas '!$H:$H,'Base Notas '!$A:$A,'Estoque '!A13,'Base Notas '!$G:$G,'Estoque '!$H$5) -> 0 | I13: =SUMIFS('Base Notas '!$H:$H,'Base Notas '!$A:$A,'Estoque '!A13,'Base Notas '!$G:$G,'Estoque '!$I$5) -> 0 | J13: =H13-E13 -> #REF! | K13: =I13-F13 -> #REF! | L13: =SUMIFS(#REF!,#REF!,'Estoque '!$L$5,#REF!,'Estoque '!A13) -> #REF! | M13: =SUMIFS(#REF!,#REF!,'Estoque '!$M$5,#REF!,'Estoque '!A13) -> #REF! | N13: =H13-L13 -> #REF! | O13: =I13-M13 -> #REF! | P13: =IFERROR(E13/L13-1,"") | Q13: =IFERROR(I13/M13-1,"")
A14: =B14&D14 -> 98883482 | B14: 98883 | C14: FAZENDA SANTA ROSA DE LIMA | D14: 482 | E14: =SUMIFS(Tratos!#REF!,Tratos!#REF!,'Estoque '!A14,Tratos!#REF!,'Estoque '!$E$5) -> #REF! | F14: =SUMIFS(Tratos!#REF!,Tratos!#REF!,'Estoque '!A14,Tratos!#REF!,'Estoque '!$F$5) -> #REF! | G14: =VLOOKUP(A14,Tratos!#REF!,7,0) -> #REF! | H14: =SUMIFS('Base Notas '!$H:$H,'Base Notas '!$A:$A,'Estoque '!A14,'Base Notas '!$G:$G,'Estoque '!$H$5) -> 0 | I14: =SUMIFS('Base Notas '!$H:$H,'Base Notas '!$A:$A,'Estoque '!A14,'Base Notas '!$G:$G,'Estoque '!$I$5) -> 0 | J14: =H14-E14 -> #REF! | K14: =I14-F14 -> #REF! | L14: =SUMIFS(#REF!,#REF!,'Estoque '!$L$5,#REF!,'Estoque '!A14) -> #REF! | M14: =SUMIFS(#REF!,#REF!,'Estoque '!$M$5,#REF!,'Estoque '!A14) -> #REF! | N14: =H14-L14 -> #REF! | O14: =I14-M14 -> #REF! | P14: =IFERROR(E14/L14-1,"") | Q14: =IFERROR(I14/M14-1,"")
A15: =B15&D15 -> 75917304 | B15: 75917 | C15: FAZENDA FAZENDINHA II | D15: 304 | E15: =SUMIFS(Tratos!#REF!,Tratos!#REF!,'Estoque '!A15,Tratos!#REF!,'Estoque '!$E$5) -> #REF! | F15: =SUMIFS(Tratos!#REF!,Tratos!#REF!,'Estoque '!A15,Tratos!#REF!,'Estoque '!$F$5) -> #REF! | G15: =VLOOKUP(A15,Tratos!#REF!,7,0) -> #REF! | H15: =SUMIFS('Base Notas '!$H:$H,'Base Notas '!$A:$A,'Estoque '!A15,'Base Notas '!$G:$G,'Estoque '!$H$5) -> 0 | I15: =SUMIFS('Base Notas '!$H:$H,'Base Notas '!$A:$A,'Estoque '!A15,'Base Notas '!$G:$G,'Estoque '!$I$5) -> 0 | J15: =H15-E15 -> #REF! | K15: =I15-F15 -> #REF! | L15: =SUMIFS(#REF!,#REF!,'Estoque '!$L$5,#REF!,'Estoque '!A15) -> #REF! | M15: =SUMIFS(#REF!,#REF!,'Estoque '!$M$5,#REF!,'Estoque '!A15) -> #REF! | N15: =H15-L15 -> #REF! | O15: =I15-M15 -> #REF! | P15: =IFERROR(E15/L15-1,"") | Q15: =IFERROR(I15/M15-1,"")
A16: =B16&D16 -> 75917303 | B16: 75917 | C16: FAZENDA FAZENDINHA II | D16: 303 | E16: =SUMIFS(Tratos!#REF!,Tratos!#REF!,'Estoque '!A16,Tratos!#REF!,'Estoque '!$E$5) -> #REF! | F16: =SUMIFS(Tratos!#REF!,Tratos!#REF!,'Estoque '!A16,Tratos!#REF!,'Estoque '!$F$5) -> #REF! | G16: =VLOOKUP(A16,Tratos!#REF!,7,0) -> #REF! | H16: =SUMIFS('Base Notas '!$H:$H,'Base Notas '!$A:$A,'Estoque '!A16,'Base Notas '!$G:$G,'Estoque '!$H$5) -> 0 | I16: =SUMIFS('Base Notas '!$H:$H,'Base Notas '!$A:$A,'Estoque '!A16,'Base Notas '!$G:$G,'Estoque '!$I$5) -> 0 | J16: =H16-E16 -> #REF! | K16: =I16-F16 -> #REF! | L16: =SUMIFS(#REF!,#REF!,'Estoque '!$L$5,#REF!,'Estoque '!A16) -> #REF! | M16: =SUMIFS(#REF!,#REF!,'Estoque '!$M$5,#REF!,'Estoque '!A16) -> #REF! | N16: =H16-L16 -> #REF! | O16: =I16-M16 -> #REF! | P16: =IFERROR(E16/L16-1,"") | Q16: =IFERROR(I16/M16-1,"")
A17: =B17&D17 -> 75864511 | B17: 75864 | C17: FAZENDA BARREIRINHO - GLEBA A | D17: 511 | E17: =SUMIFS(Tratos!#REF!,Tratos!#REF!,'Estoque '!A17,Tratos!#REF!,'Estoque '!$E$5) -> #REF! | F17: =SUMIFS(Tratos!#REF!,Tratos!#REF!,'Estoque '!A17,Tratos!#REF!,'Estoque '!$F$5) -> #REF! | G17: =VLOOKUP(A17,Tratos!#REF!,7,0) -> #REF! | H17: =SUMIFS('Base Notas '!$H:$H,'Base Notas '!$A:$A,'Estoque '!A17,'Base Notas '!$G:$G,'Estoque '!$H$5) -> 0 | I17: =SUMIFS('Base Notas '!$H:$H,'Base Notas '!$A:$A,'Estoque '!A17,'Base Notas '!$G:$G,'Estoque '!$I$5) -> 0 | J17: =H17-E17 -> #REF! | K17: =I17-F17 -> #REF! | L17: =SUMIFS(#REF!,#REF!,'Estoque '!$L$5,#REF!,'Estoque '!A17) -> #REF! | M17: =SUMIFS(#REF!,#REF!,'Estoque '!$M$5,#REF!,'Estoque '!A17) -> #REF! | N17: =H17-L17 -> #REF! | O17: =I17-M17 -> #REF! | P17: =IFERROR(E17/L17-1,"") | Q17: =IFERROR(I17/M17-1,"")
A18: =B18&D18 -> 758611 | B18: 75861 | C18: SITIO SAO LUIZ | D18: 1 | E18: =SUMIFS(Tratos!#REF!,Tratos!#REF!,'Estoque '!A18,Tratos!#REF!,'Estoque '!$E$5) -> #REF! | F18: =SUMIFS(Tratos!#REF!,Tratos!#REF!,'Estoque '!A18,Tratos!#REF!,'Estoque '!$F$5) -> #REF! | G18: =VLOOKUP(A18,Tratos!#REF!,7,0) -> #REF! | H18: =SUMIFS('Base Notas '!$H:$H,'Base Notas '!$A:$A,'Estoque '!A18,'Base Notas '!$G:$G,'Estoque '!$H$5) -> 0 | I18: =SUMIFS('Base Notas '!$H:$H,'Base Notas '!$A:$A,'Estoque '!A18,'Base Notas '!$G:$G,'Estoque '!$I$5) -> 0 | J18: =H18-E18 -> #REF! | K18: =I18-F18 -> #REF! | L18: =SUMIFS(#REF!,#REF!,'Estoque '!$L$5,#REF!,'Estoque '!A18) -> #REF! | M18: =SUMIFS(#REF!,#REF!,'Estoque '!$M$5,#REF!,'Estoque '!A18) -> #REF! | N18: =H18-L18 -> #REF! | O18: =I18-M18 -> #REF! | P18: =IFERROR(E18/L18-1,"") | Q18: =IFERROR(I18/M18-1,"")
A19: =B19&D19 -> 758441 | B19: 75844 | C19: FAZENDA SANTA TEREZINHA II | D19: 1 | E19: =SUMIFS(Tratos!#REF!,Tratos!#REF!,'Estoque '!A19,Tratos!#REF!,'Estoque '!$E$5) -> #REF! | F19: =SUMIFS(Tratos!#REF!,Tratos!#REF!,'Estoque '!A19,Tratos!#REF!,'Estoque '!$F$5) -> #REF! | G19: =VLOOKUP(A19,Tratos!#REF!,7,0) -> #REF! | H19: =SUMIFS('Base Notas '!$H:$H,'Base Notas '!$A:$A,'Estoque '!A19,'Base Notas '!$G:$G,'Estoque '!$H$5) -> 0 | I19: =SUMIFS('Base Notas '!$H:$H,'Base Notas '!$A:$A,'Estoque '!A19,'Base Notas '!$G:$G,'Estoque '!$I$5) -> 0 | J19: =H19-E19 -> #REF! | K19: =I19-F19 -> #REF! | L19: =SUMIFS(#REF!,#REF!,'Estoque '!$L$5,#REF!,'Estoque '!A19) -> #REF! | M19: =SUMIFS(#REF!,#REF!,'Estoque '!$M$5,#REF!,'Estoque '!A19) -> #REF! | N19: =H19-L19 -> #REF! | O19: =I19-M19 -> #REF! | P19: =IFERROR(E19/L19-1,"") | Q19: =IFERROR(I19/M19-1,"")
A20: =B20&D20 -> 758231 | B20: 75823 | C20: FAZENDA PINGO DAGUA I | D20: 1 | E20: =SUMIFS(Tratos!#REF!,Tratos!#REF!,'Estoque '!A20,Tratos!#REF!,'Estoque '!$E$5) -> #REF! | F20: =SUMIFS(Tratos!#REF!,Tratos!#REF!,'Estoque '!A20,Tratos!#REF!,'Estoque '!$F$5) -> #REF! | G20: =VLOOKUP(A20,Tratos!#REF!,7,0) -> #REF! | H20: =SUMIFS('Base Notas '!$H:$H,'Base Notas '!$A:$A,'Estoque '!A20,'Base Notas '!$G:$G,'Estoque '!$H$5) -> 0 | I20: =SUMIFS('Base Notas '!$H:$H,'Base Notas '!$A:$A,'Estoque '!A20,'Base Notas '!$G:$G,'Estoque '!$I$5) -> 0 | J20: =H20-E20 -> #REF! | K20: =I20-F20 -> #REF! | L20: =SUMIFS(#REF!,#REF!,'Estoque '!$L$5,#REF!,'Estoque '!A20) -> #REF! | M20: =SUMIFS(#REF!,#REF!,'Estoque '!$M$5,#REF!,'Estoque '!A20) -> #REF! | N20: =H20-L20 -> #REF! | O20: =I20-M20 -> #REF! | P20: =IFERROR(E20/L20-1,"") | Q20: =IFERROR(I20/M20-1,"")
... A39: =B39&D39 -> 74720300 | B39: 74720 | C39: FAZ PEDRA BRANCA | D39: 300 | E39: =SUMIFS(Tratos!#REF!,Tratos!#REF!,'Estoque '!A39,Tratos!#REF!,'Estoque '!$E$5) -> #REF! | F39: =SUMIFS(Tratos!#REF!,Tratos!#REF!,'Estoque '!A39,Tratos!#REF!,'Estoque '!$F$5) -> #REF! | G39: =VLOOKUP(A39,Tratos!#REF!,7,0) -> #REF! | H39: =SUMIFS('Base Notas '!$H:$H,'Base Notas '!$A:$A,'Estoque '!A39,'Base Notas '!$G:$G,'Estoque '!$H$5) -> 0 | I39: =SUMIFS('Base Notas '!$H:$H,'Base Notas '!$A:$A,'Estoque '!A39,'Base Notas '!$G:$G,'Estoque '!$I$5) -> 0 | J39: =H39-E39 -> #REF! | K39: =I39-F39 -> #REF! | L39: =SUMIFS(#REF!,#REF!,'Estoque '!$L$5,#REF!,'Estoque '!A39) -> #REF! | M39: =SUMIFS(#REF!,#REF!,'Estoque '!$M$5,#REF!,'Estoque '!A39) -> #REF! | N39: =H39-L39 -> #REF! | O39: =I39-M39 -> #REF! | P39: =IFERROR(E39/L39-1,"") | Q39: =IFERROR(I39/M39-1,"")
A40: =B40&D40 -> 74720311 | B40: 74720 | C40: FAZ PEDRA BRANCA | D40: 311 | E40: =SUMIFS(Tratos!#REF!,Tratos!#REF!,'Estoque '!A40,Tratos!#REF!,'Estoque '!$E$5) -> #REF! | F40: =SUMIFS(Tratos!#REF!,Tratos!#REF!,'Estoque '!A40,Tratos!#REF!,'Estoque '!$F$5) -> #REF! | G40: =VLOOKUP(A40,Tratos!#REF!,7,0) -> #REF! | H40: =SUMIFS('Base Notas '!$H:$H,'Base Notas '!$A:$A,'Estoque '!A40,'Base Notas '!$G:$G,'Estoque '!$H$5) -> 0 | I40: =SUMIFS('Base Notas '!$H:$H,'Base Notas '!$A:$A,'Estoque '!A40,'Base Notas '!$G:$G,'Estoque '!$I$5) -> 0 | J40: =H40-E40 -> #REF! | K40: =I40-F40 -> #REF! | L40: =SUMIFS(#REF!,#REF!,'Estoque '!$L$5,#REF!,'Estoque '!A40) -> #REF! | M40: =SUMIFS(#REF!,#REF!,'Estoque '!$M$5,#REF!,'Estoque '!A40) -> #REF! | N40: =H40-L40 -> #REF! | O40: =I40-M40 -> #REF! | P40: =IFERROR(E40/L40-1,"") | Q40: =IFERROR(I40/M40-1,"") | R40: A diferença é referente a movimentação de uma fazenda pra outra(fazendinha, barrerinho,corrego grande) | S40: A diferença é referente a movimentação de fazendas com sobra patio esplanada
A41: =B41&D41 -> 74720312 | B41: 74720 | C41: FAZ PEDRA BRANCA | D41: 312 | E41: =SUMIFS(Tratos!#REF!,Tratos!#REF!,'Estoque '!A41,Tratos!#REF!,'Estoque '!$E$5) -> #REF! | F41: =SUMIFS(Tratos!#REF!,Tratos!#REF!,'Estoque '!A41,Tratos!#REF!,'Estoque '!$F$5) -> #REF! | G41: =VLOOKUP(A41,Tratos!#REF!,7,0) -> #REF! | H41: =SUMIFS('Base Notas '!$H:$H,'Base Notas '!$A:$A,'Estoque '!A41,'Base Notas '!$G:$G,'Estoque '!$H$5) -> 0 | I41: =SUMIFS('Base Notas '!$H:$H,'Base Notas '!$A:$A,'Estoque '!A41,'Base Notas '!$G:$G,'Estoque '!$I$5) -> 0 | J41: =H41-E41 -> #REF! | K41: =I41-F41 -> #REF! | L41: =SUMIFS(#REF!,#REF!,'Estoque '!$L$5,#REF!,'Estoque '!A41) -> #REF! | M41: =SUMIFS(#REF!,#REF!,'Estoque '!$M$5,#REF!,'Estoque '!A41) -> #REF! | N41: =H41-L41 -> #REF! | O41: =I41-M41 -> #REF! | P41: =IFERROR(E41/L41-1,"") | Q41: =IFERROR(I41/M41-1,"")
A42: =B42&D42 -> 74720313 | B42: 74720 | C42: FAZ PEDRA BRANCA | D42: 313 | E42: =SUMIFS(Tratos!#REF!,Tratos!#REF!,'Estoque '!A42,Tratos!#REF!,'Estoque '!$E$5) -> #REF! | F42: =SUMIFS(Tratos!#REF!,Tratos!#REF!,'Estoque '!A42,Tratos!#REF!,'Estoque '!$F$5) -> #REF! | G42: =VLOOKUP(A42,Tratos!#REF!,7,0) -> #REF! | H42: =SUMIFS('Base Notas '!$H:$H,'Base Notas '!$A:$A,'Estoque '!A42,'Base Notas '!$G:$G,'Estoque '!$H$5) -> 0 | I42: =SUMIFS('Base Notas '!$H:$H,'Base Notas '!$A:$A,'Estoque '!A42,'Base Notas '!$G:$G,'Estoque '!$I$5) -> 0 | J42: =H42-E42 -> #REF! | K42: =I42-F42 -> #REF! | L42: =SUMIFS(#REF!,#REF!,'Estoque '!$L$5,#REF!,'Estoque '!A42) -> #REF! | M42: =SUMIFS(#REF!,#REF!,'Estoque '!$M$5,#REF!,'Estoque '!A42) -> #REF! | N42: =H42-L42 -> #REF! | O42: =I42-M42 -> #REF! | P42: =IFERROR(E42/L42-1,"") | Q42: =IFERROR(I42/M42-1,"")
A43: =B43&D43 -> 746731 | B43: 74673 | C43: Fazenda Olhos D'agua | D43: 1 | E43: =SUMIFS(Tratos!#REF!,Tratos!#REF!,'Estoque '!A43,Tratos!#REF!,'Estoque '!$E$5) -> #REF! | F43: =SUMIFS(Tratos!#REF!,Tratos!#REF!,'Estoque '!A43,Tratos!#REF!,'Estoque '!$F$5) -> #REF! | G43: =VLOOKUP(A43,Tratos!#REF!,7,0) -> #REF! | H43: =SUMIFS('Base Notas '!$H:$H,'Base Notas '!$A:$A,'Estoque '!A43,'Base Notas '!$G:$G,'Estoque '!$H$5) -> 0 | I43: =SUMIFS('Base Notas '!$H:$H,'Base Notas '!$A:$A,'Estoque '!A43,'Base Notas '!$G:$G,'Estoque '!$I$5) -> 0 | J43: =H43-E43 -> #REF! | K43: =I43-F43 -> #REF! | L43: =SUMIFS(#REF!,#REF!,'Estoque '!$L$5,#REF!,'Estoque '!A43) -> #REF! | M43: =SUMIFS(#REF!,#REF!,'Estoque '!$M$5,#REF!,'Estoque '!A43) -> #REF! | N43: =H43-L43 -> #REF! | O43: =I43-M43 -> #REF! | P43: =IFERROR(E43/L43-1,"") | Q43: =IFERROR(I43/M43-1,"")
A44: =B44&D44 -> 74532194 | B44: 74532 | C44: FAZ ESTANCIA BONANZA | D44: 194 | E44: =SUMIFS(Tratos!#REF!,Tratos!#REF!,'Estoque '!A44,Tratos!#REF!,'Estoque '!$E$5) -> #REF! | F44: =SUMIFS(Tratos!#REF!,Tratos!#REF!,'Estoque '!A44,Tratos!#REF!,'Estoque '!$F$5) -> #REF! | G44: =VLOOKUP(A44,Tratos!#REF!,7,0) -> #REF! | H44: =SUMIFS('Base Notas '!$H:$H,'Base Notas '!$A:$A,'Estoque '!A44,'Base Notas '!$G:$G,'Estoque '!$H$5) -> 0 | I44: =SUMIFS('Base Notas '!$H:$H,'Base Notas '!$A:$A,'Estoque '!A44,'Base Notas '!$G:$G,'Estoque '!$I$5) -> 0 | J44: =H44-E44 -> #REF! | K44: =I44-F44 -> #REF! | L44: =SUMIFS(#REF!,#REF!,'Estoque '!$L$5,#REF!,'Estoque '!A44) -> #REF! | M44: =SUMIFS(#REF!,#REF!,'Estoque '!$M$5,#REF!,'Estoque '!A44) -> #REF! | N44: =H44-L44 -> #REF! | O44: =I44-M44 -> #REF! | P44: =IFERROR(E44/L44-1,"") | Q44: =IFERROR(I44/M44-1,"") | S44: Sobrou 56t na bonanza
A45: =B45&D45 -> 74532195 | B45: 74532 | C45: FAZ ESTANCIA BONANZA | D45: 195 | E45: =SUMIFS(Tratos!#REF!,Tratos!#REF!,'Estoque '!A45,Tratos!#REF!,'Estoque '!$E$5) -> #REF! | F45: =SUMIFS(Tratos!#REF!,Tratos!#REF!,'Estoque '!A45,Tratos!#REF!,'Estoque '!$F$5) -> #REF! | G45: =VLOOKUP(A45,Tratos!#REF!,7,0) -> #REF! | H45: =SUMIFS('Base Notas '!$H:$H,'Base Notas '!$A:$A,'Estoque '!A45,'Base Notas '!$G:$G,'Estoque '!$H$5) -> 0 | I45: =SUMIFS('Base Notas '!$H:$H,'Base Notas '!$A:$A,'Estoque '!A45,'Base Notas '!$G:$G,'Estoque '!$I$5) -> 0 | J45: =H45-E45 -> #REF! | K45: =I45-F45 -> #REF! | L45: =SUMIFS(#REF!,#REF!,'Estoque '!$L$5,#REF!,'Estoque '!A45) -> #REF! | M45: =SUMIFS(#REF!,#REF!,'Estoque '!$M$5,#REF!,'Estoque '!A45) -> #REF! | N45: =H45-L45 -> #REF! | O45: =I45-M45 -> #REF! | P45: =IFERROR(E45/L45-1,"") | Q45: =IFERROR(I45/M45-1,"") | R45: Verificar no engate bonanza sobra
A46: =B46&D46 -> 74492193 | B46: 74492 | C46: FAZ PRIMAVERA | D46: 193 | E46: =SUMIFS(Tratos!#REF!,Tratos!#REF!,'Estoque '!A46,Tratos!#REF!,'Estoque '!$E$5) -> #REF! | F46: =SUMIFS(Tratos!#REF!,Tratos!#REF!,'Estoque '!A46,Tratos!#REF!,'Estoque '!$F$5) -> #REF! | G46: =VLOOKUP(A46,Tratos!#REF!,7,0) -> #REF! | H46: =SUMIFS('Base Notas '!$H:$H,'Base Notas '!$A:$A,'Estoque '!A46,'Base Notas '!$G:$G,'Estoque '!$H$5) -> 0 | I46: =SUMIFS('Base Notas '!$H:$H,'Base Notas '!$A:$A,'Estoque '!A46,'Base Notas '!$G:$G,'Estoque '!$I$5) -> 0 | J46: =H46-E46 -> #REF! | K46: =I46-F46 -> #REF! | L46: =SUMIFS(#REF!,#REF!,'Estoque '!$L$5,#REF!,'Estoque '!A46) -> #REF! | M46: =SUMIFS(#REF!,#REF!,'Estoque '!$M$5,#REF!,'Estoque '!A46) -> #REF! | N46: =H46-L46 -> #REF! | O46: =I46-M46 -> #REF! | P46: =IFERROR(E46/L46-1,"") | Q46: =IFERROR(I46/M46-1,"") | R46: sobrou 71t primavera
A47: =B47&D47 -> 7430314 | B47: 74303 | C47: ST SAO JOSE | D47: 14 | E47: =SUMIFS(Tratos!#REF!,Tratos!#REF!,'Estoque '!A47,Tratos!#REF!,'Estoque '!$E$5) -> #REF! | F47: =SUMIFS(Tratos!#REF!,Tratos!#REF!,'Estoque '!A47,Tratos!#REF!,'Estoque '!$F$5) -> #REF! | G47: =VLOOKUP(A47,Tratos!#REF!,7,0) -> #REF! | H47: =SUMIFS('Base Notas '!$H:$H,'Base Notas '!$A:$A,'Estoque '!A47,'Base Notas '!$G:$G,'Estoque '!$H$5) -> 0 | I47: =SUMIFS('Base Notas '!$H:$H,'Base Notas '!$A:$A,'Estoque '!A47,'Base Notas '!$G:$G,'Estoque '!$I$5) -> 0 | J47: =H47-E47 -> #REF! | K47: =I47-F47 -> #REF! | L47: =SUMIFS(#REF!,#REF!,'Estoque '!$L$5,#REF!,'Estoque '!A47) -> #REF! | M47: =SUMIFS(#REF!,#REF!,'Estoque '!$M$5,#REF!,'Estoque '!A47) -> #REF! | N47: =H47-L47 -> #REF! | O47: =I47-M47 -> #REF! | P47: =IFERROR(E47/L47-1,"") | Q47: =IFERROR(I47/M47-1,"")
A48: =B48&D48 -> 742121 | B48: 74212 | C48: SIT RECANTO DOS PASSAROS | D48: 1 | E48: =SUMIFS(Tratos!#REF!,Tratos!#REF!,'Estoque '!A48,Tratos!#REF!,'Estoque '!$E$5) -> #REF! | F48: =SUMIFS(Tratos!#REF!,Tratos!#REF!,'Estoque '!A48,Tratos!#REF!,'Estoque '!$F$5) -> #REF! | G48: =VLOOKUP(A48,Tratos!#REF!,7,0) -> #REF! | H48: =SUMIFS('Base Notas '!$H:$H,'Base Notas '!$A:$A,'Estoque '!A48,'Base Notas '!$G:$G,'Estoque '!$H$5) -> 0 | I48: =SUMIFS('Base Notas '!$H:$H,'Base Notas '!$A:$A,'Estoque '!A48,'Base Notas '!$G:$G,'Estoque '!$I$5) -> 0 | J48: =H48-E48 -> #REF! | K48: =I48-F48 -> #REF! | L48: =SUMIFS(#REF!,#REF!,'Estoque '!$L$5,#REF!,'Estoque '!A48) -> #REF! | M48: =SUMIFS(#REF!,#REF!,'Estoque '!$M$5,#REF!,'Estoque '!A48) -> #REF! | N48: =H48-L48 -> #REF! | O48: =I48-M48 -> #REF! | P48: =IFERROR(E48/L48-1,"") | Q48: =IFERROR(I48/M48-1,"")
A49: =B49&D49 -> 742101 | B49: 74210 | C49: FAZ FORZA ITALIA | D49: 1 | E49: =SUMIFS(Tratos!#REF!,Tratos!#REF!,'Estoque '!A49,Tratos!#REF!,'Estoque '!$E$5) -> #REF! | F49: =SUMIFS(Tratos!#REF!,Tratos!#REF!,'Estoque '!A49,Tratos!#REF!,'Estoque '!$F$5) -> #REF! | G49: =VLOOKUP(A49,Tratos!#REF!,7,0) -> #REF! | H49: =SUMIFS('Base Notas '!$H:$H,'Base Notas '!$A:$A,'Estoque '!A49,'Base Notas '!$G:$G,'Estoque '!$H$5) -> 0 | I49: =SUMIFS('Base Notas '!$H:$H,'Base Notas '!$A:$A,'Estoque '!A49,'Base Notas '!$G:$G,'Estoque '!$I$5) -> 0 | J49: =H49-E49 -> #REF! | K49: =I49-F49 -> #REF! | L49: =SUMIFS(#REF!,#REF!,'Estoque '!$L$5,#REF!,'Estoque '!A49) -> #REF! | M49: =SUMIFS(#REF!,#REF!,'Estoque '!$M$5,#REF!,'Estoque '!A49) -> #REF! | N49: =H49-L49 -> #REF! | O49: =I49-M49 -> #REF! | P49: =IFERROR(E49/L49-1,"") | Q49: =IFERROR(I49/M49-1,"")
A50: =B50&D50 -> 742102 | B50: 74210 | C50: FAZ FORZA ITALIA | D50: 2 | E50: =SUMIFS(Tratos!#REF!,Tratos!#REF!,'Estoque '!A50,Tratos!#REF!,'Estoque '!$E$5) -> #REF! | F50: =SUMIFS(Tratos!#REF!,Tratos!#REF!,'Estoque '!A50,Tratos!#REF!,'Estoque '!$F$5) -> #REF! | G50: =VLOOKUP(A50,Tratos!#REF!,7,0) -> #REF! | H50: =SUMIFS('Base Notas '!$H:$H,'Base Notas '!$A:$A,'Estoque '!A50,'Base Notas '!$G:$G,'Estoque '!$H$5) -> 0 | I50: =SUMIFS('Base Notas '!$H:$H,'Base Notas '!$A:$A,'Estoque '!A50,'Base Notas '!$G:$G,'Estoque '!$I$5) -> 0 | J50: =H50-E50 -> #REF! | K50: =I50-F50 -> #REF! | L50: =SUMIFS(#REF!,#REF!,'Estoque '!$L$5,#REF!,'Estoque '!A50) -> #REF! | M50: =SUMIFS(#REF!,#REF!,'Estoque '!$M$5,#REF!,'Estoque '!A50) -> #REF! | N50: =H50-L50 -> #REF! | O50: =I50-M50 -> #REF! | P50: =IFERROR(E50/L50-1,"") | Q50: =IFERROR(I50/M50-1,"")
A51: =B51&D51 -> 741921 | B51: 74192 | C51: SIT SAO PEDRO | D51: 1 | E51: =SUMIFS(Tratos!#REF!,Tratos!#REF!,'Estoque '!A51,Tratos!#REF!,'Estoque '!$E$5) -> #REF! | F51: =SUMIFS(Tratos!#REF!,Tratos!#REF!,'Estoque '!A51,Tratos!#REF!,'Estoque '!$F$5) -> #REF! | G51: =VLOOKUP(A51,Tratos!#REF!,7,0) -> #REF! | H51: =SUMIFS('Base Notas '!$H:$H,'Base Notas '!$A:$A,'Estoque '!A51,'Base Notas '!$G:$G,'Estoque '!$H$5) -> 0 | I51: =SUMIFS('Base Notas '!$H:$H,'Base Notas '!$A:$A,'Estoque '!A51,'Base Notas '!$G:$G,'Estoque '!$I$5) -> 0 | J51: =H51-E51 -> #REF! | K51: =I51-F51 -> #REF! | L51: =SUMIFS(#REF!,#REF!,'Estoque '!$L$5,#REF!,'Estoque '!A51) -> #REF! | M51: =SUMIFS(#REF!,#REF!,'Estoque '!$M$5,#REF!,'Estoque '!A51) -> #REF! | N51: =H51-L51 -> #REF! | O51: =I51-M51 -> #REF! | P51: =IFERROR(E51/L51-1,"") | Q51: =IFERROR(I51/M51-1,"")
A52: =B52&D52 -> 741571 | B52: 74157 | C52: FAZ SAO FRANCISCO | D52: 1 | E52: =SUMIFS(Tratos!#REF!,Tratos!#REF!,'Estoque '!A52,Tratos!#REF!,'Estoque '!$E$5) -> #REF! | F52: =SUMIFS(Tratos!#REF!,Tratos!#REF!,'Estoque '!A52,Tratos!#REF!,'Estoque '!$F$5) -> #REF! | G52: =VLOOKUP(A52,Tratos!#REF!,7,0) -> #REF! | H52: =SUMIFS('Base Notas '!$H:$H,'Base Notas '!$A:$A,'Estoque '!A52,'Base Notas '!$G:$G,'Estoque '!$H$5) -> 0 | I52: =SUMIFS('Base Notas '!$H:$H,'Base Notas '!$A:$A,'Estoque '!A52,'Base Notas '!$G:$G,'Estoque '!$I$5) -> 0 | J52: =H52-E52 -> #REF! | K52: =I52-F52 -> #REF! | L52: =SUMIFS(#REF!,#REF!,'Estoque '!$L$5,#REF!,'Estoque '!A52) -> #REF! | M52: =SUMIFS(#REF!,#REF!,'Estoque '!$M$5,#REF!,'Estoque '!A52) -> #REF! | N52: =H52-L52 -> #REF! | O52: =I52-M52 -> #REF! | P52: =IFERROR(E52/L52-1,"") | Q52: =IFERROR(I52/M52-1,"")
A53: =B53&D53 -> 74154504 | B53: 74154 | C53: SIT SAO JOSE | D53: 504 | E53: =SUMIFS(Tratos!#REF!,Tratos!#REF!,'Estoque '!A53,Tratos!#REF!,'Estoque '!$E$5) -> #REF! | F53: =SUMIFS(Tratos!#REF!,Tratos!#REF!,'Estoque '!A53,Tratos!#REF!,'Estoque '!$F$5) -> #REF! | G53: =VLOOKUP(A53,Tratos!#REF!,7,0) -> #REF! | H53: =SUMIFS('Base Notas '!$H:$H,'Base Notas '!$A:$A,'Estoque '!A53,'Base Notas '!$G:$G,'Estoque '!$H$5) -> 0 | I53: =SUMIFS('Base Notas '!$H:$H,'Base Notas '!$A:$A,'Estoque '!A53,'Base Notas '!$G:$G,'Estoque '!$I$5) -> 0 | J53: =H53-E53 -> #REF! | K53: =I53-F53 -> #REF! | L53: =SUMIFS(#REF!,#REF!,'Estoque '!$L$5,#REF!,'Estoque '!A53) -> #REF! | M53: =SUMIFS(#REF!,#REF!,'Estoque '!$M$5,#REF!,'Estoque '!A53) -> #REF! | N53: =H53-L53 -> #REF! | O53: =I53-M53 -> #REF! | P53: =IFERROR(E53/L53-1,"") | Q53: =IFERROR(I53/M53-1,"")
A54: =B54&D54 -> 74119780 | B54: 74119 | C54: FAZENDA SANTA TEREZA | D54: 780 | E54: =SUMIFS(Tratos!#REF!,Tratos!#REF!,'Estoque '!A54,Tratos!#REF!,'Estoque '!$E$5) -> #REF! | F54: =SUMIFS(Tratos!#REF!,Tratos!#REF!,'Estoque '!A54,Tratos!#REF!,'Estoque '!$F$5) -> #REF! | G54: =VLOOKUP(A54,Tratos!#REF!,7,0) -> #REF! | H54: =SUMIFS('Base Notas '!$H:$H,'Base Notas '!$A:$A,'Estoque '!A54,'Base Notas '!$G:$G,'Estoque '!$H$5) -> 0 | I54: =SUMIFS('Base Notas '!$H:$H,'Base Notas '!$A:$A,'Estoque '!A54,'Base Notas '!$G:$G,'Estoque '!$I$5) -> 0 | J54: =H54-E54 -> #REF! | K54: =I54-F54 -> #REF! | L54: =SUMIFS(#REF!,#REF!,'Estoque '!$L$5,#REF!,'Estoque '!A54) -> #REF! | M54: =SUMIFS(#REF!,#REF!,'Estoque '!$M$5,#REF!,'Estoque '!A54) -> #REF! | N54: =H54-L54 -> #REF! | O54: =I54-M54 -> #REF! | P54: =IFERROR(E54/L54-1,"") | Q54: =IFERROR(I54/M54-1,"")
A55: =B55&D55 -> 74119781 | B55: 74119 | C55: FAZENDA SANTA TEREZA | D55: 781 | E55: =SUMIFS(Tratos!#REF!,Tratos!#REF!,'Estoque '!A55,Tratos!#REF!,'Estoque '!$E$5) -> #REF! | F55: =SUMIFS(Tratos!#REF!,Tratos!#REF!,'Estoque '!A55,Tratos!#REF!,'Estoque '!$F$5) -> #REF! | G55: =VLOOKUP(A55,Tratos!#REF!,7,0) -> #REF! | H55: =SUMIFS('Base Notas '!$H:$H,'Base Notas '!$A:$A,'Estoque '!A55,'Base Notas '!$G:$G,'Estoque '!$H$5) -> 0 | I55: =SUMIFS('Base Notas '!$H:$H,'Base Notas '!$A:$A,'Estoque '!A55,'Base Notas '!$G:$G,'Estoque '!$I$5) -> 0 | J55: =H55-E55 -> #REF! | K55: =I55-F55 -> #REF! | L55: =SUMIFS(#REF!,#REF!,'Estoque '!$L$5,#REF!,'Estoque '!A55) -> #REF! | M55: =SUMIFS(#REF!,#REF!,'Estoque '!$M$5,#REF!,'Estoque '!A55) -> #REF! | N55: =H55-L55 -> #REF! | O55: =I55-M55 -> #REF! | P55: =IFERROR(E55/L55-1,"") | Q55: =IFERROR(I55/M55-1,"")
A56: =B56&D56 -> 74119788 | B56: 74119 | C56: FAZENDA SANTA TEREZA | D56: 788 | E56: =SUMIFS(Tratos!#REF!,Tratos!#REF!,'Estoque '!A56,Tratos!#REF!,'Estoque '!$E$5) -> #REF! | F56: =SUMIFS(Tratos!#REF!,Tratos!#REF!,'Estoque '!A56,Tratos!#REF!,'Estoque '!$F$5) -> #REF! | G56: =VLOOKUP(A56,Tratos!#REF!,7,0) -> #REF! | H56: =SUMIFS('Base Notas '!$H:$H,'Base Notas '!$A:$A,'Estoque '!A56,'Base Notas '!$G:$G,'Estoque '!$H$5) -> 0 | I56: =SUMIFS('Base Notas '!$H:$H,'Base Notas '!$A:$A,'Estoque '!A56,'Base Notas '!$G:$G,'Estoque '!$I$5) -> 0 | J56: =H56-E56 -> #REF! | K56: =I56-F56 -> #REF! | L56: =SUMIFS(#REF!,#REF!,'Estoque '!$L$5,#REF!,'Estoque '!A56) -> #REF! | M56: =SUMIFS(#REF!,#REF!,'Estoque '!$M$5,#REF!,'Estoque '!A56) -> #REF! | N56: =H56-L56 -> #REF! | O56: =I56-M56 -> #REF! | P56: =IFERROR(E56/L56-1,"") | Q56: =IFERROR(I56/M56-1,"")
A57: =B57&D57 -> 74119789 | B57: 74119 | C57: FAZENDA SANTA TEREZA | D57: 789 | E57: =SUMIFS(Tratos!#REF!,Tratos!#REF!,'Estoque '!A57,Tratos!#REF!,'Estoque '!$E$5) -> #REF! | F57: =SUMIFS(Tratos!#REF!,Tratos!#REF!,'Estoque '!A57,Tratos!#REF!,'Estoque '!$F$5) -> #REF! | G57: =VLOOKUP(A57,Tratos!#REF!,7,0) -> #REF! | H57: =SUMIFS('Base Notas '!$H:$H,'Base Notas '!$A:$A,'Estoque '!A57,'Base Notas '!$G:$G,'Estoque '!$H$5) -> 0 | I57: =SUMIFS('Base Notas '!$H:$H,'Base Notas '!$A:$A,'Estoque '!A57,'Base Notas '!$G:$G,'Estoque '!$I$5) -> 0 | J57: =H57-E57 -> #REF! | K57: =I57-F57 -> #REF! | L57: =SUMIFS(#REF!,#REF!,'Estoque '!$L$5,#REF!,'Estoque '!A57) -> #REF! | M57: =SUMIFS(#REF!,#REF!,'Estoque '!$M$5,#REF!,'Estoque '!A57) -> #REF! | N57: =H57-L57 -> #REF! | O57: =I57-M57 -> #REF! | P57: =IFERROR(E57/L57-1,"") | Q57: =IFERROR(I57/M57-1,"")
A58: =B58&D58 -> 740881 | B58: 74088 | C58: SIT DOS MENINOS | D58: 1 | E58: =SUMIFS(Tratos!#REF!,Tratos!#REF!,'Estoque '!A58,Tratos!#REF!,'Estoque '!$E$5) -> #REF! | F58: =SUMIFS(Tratos!#REF!,Tratos!#REF!,'Estoque '!A58,Tratos!#REF!,'Estoque '!$F$5) -> #REF! | G58: =VLOOKUP(A58,Tratos!#REF!,7,0) -> #REF! | H58: =SUMIFS('Base Notas '!$H:$H,'Base Notas '!$A:$A,'Estoque '!A58,'Base Notas '!$G:$G,'Estoque '!$H$5) -> 0 | I58: =SUMIFS('Base Notas '!$H:$H,'Base Notas '!$A:$A,'Estoque '!A58,'Base Notas '!$G:$G,'Estoque '!$I$5) -> 0 | J58: =H58-E58 -> #REF! | K58: =I58-F58 -> #REF! | L58: =SUMIFS(#REF!,#REF!,'Estoque '!$L$5,#REF!,'Estoque '!A58) -> #REF! | M58: =SUMIFS(#REF!,#REF!,'Estoque '!$M$5,#REF!,'Estoque '!A58) -> #REF! | N58: =H58-L58 -> #REF! | O58: =I58-M58 -> #REF! | P58: =IFERROR(E58/L58-1,"") | Q58: =IFERROR(I58/M58-1,"")
...

Sheet Inventario
A1: Chave Insumo | B1: ChavaFZT | C1: CHAVE | D1: SAFRA | E1: REGIAO | F1: EMPRESA | G1: EMPDESC | H1: MOD | I1: NUM | J1: FAZENDA | K1: ZONA | L1: TALHAO | M1: BLOCO | N1: BLOCO_PLAN | O1: AREA_HA | P1: AREA_DANO | Q1: VARIED | R1: MAN_HIPOT | S1: COD_ESTAGIO | T1: ESTAGIO | U1: TIPO_PROP | V1: DATA_PLANTIO | W1: FRENTE | X1: DEVOLUCAO | Y1: REFORMA | Z1: TP_REFORMA | AA1: SIST_PLANT | AB1: CQUEIMA_E | AC1: APALHA_E | AD1: VINHACA_E | AE1: AJIFER_E | AF1: TORTAF_E | AG1: SISTEMA_COL | AH1: DIST_TERRA | AI1: DIST_ASFALTO | AJ1: DIST_HIDR | AK1: UNID_IND | AL1: AMBIENTE | AM1: ESPAC | AN1: AREA_PROD | AO1: TCH_PROD | AP1: TON_ESTIM | AQ1: AREA_REEST | AR1: TCH_REEST | AS1: TON_REEST | AT1: AREA_REEST2 | AU1: TCH_REEST2 | AV1: TON_REEST2 | AW1: AREA_REEST3 | AX1: TCH_REEST3 | AY1: TON_REEST3 | AZ1: AREA_MUDA | BA1: TCH_MUDA | BB1: TON_MUDA | BC1: SIT_TALHAO | BD1: DATA_FECHA | BE1: CANA_ENT | BF1: ADMIN | BG1: FORNEC | BH1: Dias | BI1: Já aplicou?
B2: =CONCATENATE(I2,K2,L2) -> 900111 | C2: =CONCATENATE(I2,K2) -> 90011 | D2: 22526 | E2: 4-Ipaussu | F2: 61 | G2: Ipau | H2: 71 | I2: 9001 | J2: FAZENDA SANTA HELENA | K2: 1 | L2: 1 | M2: 2 | O2: 18.59 | P2: 0 | Q2: CTC9005 | R2: Tardia | S2: 5 | T2: 4o. Corte | U2: 1 | V2: 44268 | W2: 350 | X2: N | Y2: N | AB2: N | AC2: S | AD2: N | AE2: N | AF2: N | AG2: 2 | AH2: 0 | AI2: 5 | AJ2: 0 | AK2: 61 | AL2: mC | AM2: 0,9 x 1,5-Alternado | AN2: 18.59 | AO2: 84.74 | AP2: 1575.3166 | AQ2: 18.59 | AR2: 75.07 | AS2: 1395.5513 | BC2: Fechado | BD2: 45830 | BE2: 583.34 | BF2: Propria | BG2: RAIZEN ENERGIA S/A - FILIAL IPAUSSU | BH2: =TODAY()-BD2 -> 293
B3: =CONCATENATE(I3,K3,L3) -> 900112 | C3: =CONCATENATE(I3,K3) -> 90011 | D3: 22526 | E3: 4-Ipaussu | F3: 61 | G3: Ipau | H3: 71 | I3: 9001 | J3: FAZENDA SANTA HELENA | K3: 1 | L3: 2 | M3: 2 | O3: 5.08 | P3: 0 | Q3: CTC9005 | R3: Tardia | S3: 5 | T3: 4o. Corte | U3: 1 | V3: 44266 | W3: 350 | X3: N | Y3: N | AB3: N | AC3: S | AD3: N | AE3: N | AF3: N | AG3: 2 | AH3: 0 | AI3: 5 | AJ3: 0 | AK3: 61 | AL3: mC | AM3: 0,9 x 1,5-Alternado | AN3: 5.08 | AO3: 84.74 | AP3: 430.4792 | AQ3: 5.08 | AR3: 75.07 | AS3: 381.3556 | BC3: Fechado | BD3: 45830 | BE3: 542.29 | BF3: Propria | BG3: RAIZEN ENERGIA S/A - FILIAL IPAUSSU | BH3: =TODAY()-BD3 -> 293
B4: =CONCATENATE(I4,K4,L4) -> 900113 | C4: =CONCATENATE(I4,K4) -> 90011 | D4: 22526 | E4: 4-Ipaussu | F4: 61 | G4: Ipau | H4: 71 | I4: 9001 | J4: FAZENDA SANTA HELENA | K4: 1 | L4: 3 | M4: 2 | O4: 26.06 | P4: 0 | Q4: CTC9005 | R4: Tardia | S4: 5 | T4: 4o. Corte | U4: 1 | V4: 44268 | W4: 350 | X4: N | Y4: N | AB4: N | AC4: S | AD4: N | AE4: N | AF4: N | AG4: 2 | AH4: 0 | AI4: 5 | AJ4: 0 | AK4: 61 | AL4: mC | AM4: 0,9 x 1,5-Alternado | AN4: 26.06 | AO4: 84.74 | AP4: 2208.3244 | AQ4: 26.06 | AR4: 75.07 | AS4: 1956.3242 | BC4: Fechado | BD4: 45830 | BE4: 2591.48 | BF4: Propria | BG4: RAIZEN ENERGIA S/A - FILIAL IPAUSSU | BH4: =TODAY()-BD4 -> 293
B5: =CONCATENATE(I5,K5,L5) -> 900114 | C5: =CONCATENATE(I5,K5) -> 90011 | D5: 22526 | E5: 4-Ipaussu | F5: 61 | G5: Ipau | H5: 71 | I5: 9001 | J5: FAZENDA SANTA HELENA | K5: 1 | L5: 4 | M5: 2 | O5: 2.08 | P5: 0 | Q5: CTC9005 | R5: Tardia | S5: 5 | T5: 4o. Corte | U5: 1 | V5: 44268 | W5: 350 | X5: N | Y5: N | AB5: N | AC5: S | AD5: N | AE5: N | AF5: N | AG5: 2 | AH5: 0 | AI5: 5 | AJ5: 0 | AK5: 61 | AL5: mC | AM5: 0,9 x 1,5-Alternado | AN5: 2.08 | AO5: 84.74 | AP5: 176.2592 | AQ5: 2.08 | AR5: 75.07 | AS5: 156.1456 | BC5: Fechado | BD5: 45830 | BE5: 147.5 | BF5: Propria | BG5: RAIZEN ENERGIA S/A - FILIAL IPAUSSU | BH5: =TODAY()-BD5 -> 293
B6: =CONCATENATE(I6,K6,L6) -> 900115 | C6: =CONCATENATE(I6,K6) -> 90011 | D6: 22526 | E6: 4-Ipaussu | F6: 61 | G6: Ipau | H6: 71 | I6: 9001 | J6: FAZENDA SANTA HELENA | K6: 1 | L6: 5 | M6: 2 | O6: 0.95 | P6: 0 | Q6: CTC9005 | R6: Tardia | S6: 5 | T6: 4o. Corte | U6: 1 | V6: 44268 | W6: 350 | X6: N | Y6: N | AB6: N | AC6: S | AD6: N | AE6: N | AF6: N | AG6: 2 | AH6: 0 | AI6: 5 | AJ6: 0 | AK6: 61 | AL6: mC | AM6: 0,9 x 1,5-Alternado | AN6: 0.95 | AO6: 84.74 | AP6: 80.503 | AQ6: 0.95 | AR6: 75.07 | AS6: 71.3165 | BC6: Fechado | BD6: 45830 | BE6: 98.47 | BF6: Propria | BG6: RAIZEN ENERGIA S/A - FILIAL IPAUSSU | BH6: =TODAY()-BD6 -> 293
B7: =CONCATENATE(I7,K7,L7) -> 900116 | C7: =CONCATENATE(I7,K7) -> 90011 | D7: 22526 | E7: 4-Ipaussu | F7: 61 | G7: Ipau | H7: 71 | I7: 9001 | J7: FAZENDA SANTA HELENA | K7: 1 | L7: 6 | M7: 1 | N7: 1 | O7: 10.92 | P7: 0 | Q7: RB966928 | R7: Tardia | S7: 10 | T7: 9o. Corte | U7: 1 | V7: 42731 | W7: 352 | X7: N | Y7: N | AB7: N | AC7: S | AD7: N | AE7: N | AF7: N | AG7: 2 | AH7: 0 | AI7: 5 | AJ7: 0 | AK7: 61 | AL7: mC | AM7: 0,9 x 1,5-Alternado | AN7: 10.92 | AO7: 39.65 | AP7: 432.978 | AQ7: 10.92 | AR7: 45.07 | AS7: 492.1644 | BC7: Fechado | BD7: 45830 | BE7: 1105.74 | BF7: Propria | BG7: RAIZEN ENERGIA S/A - FILIAL IPAUSSU | BH7: =TODAY()-BD7 -> 293
B8: =CONCATENATE(I8,K8,L8) -> 900117 | C8: =CONCATENATE(I8,K8) -> 90011 | D8: 22526 | E8: 4-Ipaussu | F8: 61 | G8: Ipau | H8: 71 | I8: 9001 | J8: FAZENDA SANTA HELENA | K8: 1 | L8: 7 | M8: 1 | N8: 1 | O8: 17.84 | P8: 0 | Q8: RB966928 | R8: Tardia | S8: 10 | T8: 9o. Corte | U8: 1 | V8: 42731 | W8: 352 | X8: N | Y8: N | AB8: N | AC8: S | AD8: N | AE8: N | AF8: N | AG8: 2 | AH8: 0 | AI8: 5 | AJ8: 0 | AK8: 61 | AL8: mC | AM8: 0,9 x 1,5-Alternado | AN8: 17.84 | AO8: 39.65 | AP8: 707.356 | AQ8: 17.84 | AR8: 45.07 | AS8: 804.0488 | BC8: Fechado | BD8: 45830 | BE8: 1293.27 | BF8: Propria | BG8: RAIZEN ENERGIA S/A - FILIAL IPAUSSU | BH8: =TODAY()-BD8 -> 293
B9: =CONCATENATE(I9,K9,L9) -> 900118 | C9: =CONCATENATE(I9,K9) -> 90011 | D9: 22526 | E9: 4-Ipaussu | F9: 61 | G9: Ipau | H9: 71 | I9: 9001 | J9: FAZENDA SANTA HELENA | K9: 1 | L9: 8 | M9: 2 | O9: 6.27 | P9: 0 | Q9: CTC9005 | R9: Tardia | S9: 5 | T9: 4o. Corte | U9: 1 | V9: 44267 | W9: 350 | X9: N | Y9: N | AB9: N | AC9: S | AD9: N | AE9: N | AF9: N | AG9: 2 | AH9: 0 | AI9: 5 | AJ9: 0 | AK9: 61 | AL9: mC | AM9: 0,9 x 1,5-Alternado | AN9: 6.27 | AO9: 84.74 | AP9: 531.3198 | AQ9: 6.27 | AR9: 75.07 | AS9: 470.6889 | BC9: Fechado | BD9: 45830 | BE9: 369.49 | BF9: Propria | BG9: RAIZEN ENERGIA S/A - FILIAL IPAUSSU | BH9: =TODAY()-BD9 -> 293
B10: =CONCATENATE(I10,K10,L10) -> 900119 | C10: =CONCATENATE(I10,K10) -> 90011 | D10: 22526 | E10: 4-Ipaussu | F10: 61 | G10: Ipau | H10: 71 | I10: 9001 | J10: FAZENDA SANTA HELENA | K10: 1 | L10: 9 | M10: 2 | O10: 19.31 | P10: 0 | Q10: CTC9005 | R10: Tardia | S10: 5 | T10: 4o. Corte | U10: 1 | V10: 44267 | W10: 350 | X10: N | Y10: N | AB10: N | AC10: S | AD10: N | AE10: N | AF10: N | AG10: 2 | AH10: 0 | AI10: 5 | AJ10: 0 | AK10: 61 | AL10: mC | AM10: 0,9 x 1,5-Alternado | AN10: 19.31 | AO10: 84.74 | AP10: 1636.3294 | AQ10: 19.31 | AR10: 75.07 | AS10: 1449.6017 | BC10: Fechado | BD10: 45830 | BE10: 1903.16 | BF10: Propria | BG10: RAIZEN ENERGIA S/A - FILIAL IPAUSSU | BH10: =TODAY()-BD10 -> 293
B11: =CONCATENATE(I11,K11,L11) -> 900121 | C11: =CONCATENATE(I11,K11) -> 90012 | D11: 22526 | E11: 4-Ipaussu | F11: 61 | G11: Ipau | H11: 71 | I11: 9001 | J11: FAZENDA SANTA HELENA | K11: 2 | L11: 1 | M11: 6 | N11: 2 | O11: 10.95 | P11: 0 | Q11: VIVEIRO | R11: Super Precoce | S11: 4 | T11: 3o. Corte | U11: 1 | V11: 44525 | W11: 355 | X11: N | Y11: N | AB11: N | AC11: S | AD11: N | AE11: N | AF11: N | AG11: 2 | AH11: 0 | AI11: 7 | AJ11: 0 | AK11: 61 | AL11: mC | AM11: 0,9 x 1,5-Alternado | AN11: 10.95 | AO11: 90.58 | AP11: 991.851 | AQ11: 10.95 | AR11: 81.07 | AS11: 887.7165 | BC11: Fechado | BD11: 45853 | BE11: 805.51 | BF11: Propria | BG11: RAIZEN ENERGIA S/A - FILIAL IPAUSSU | BH11: =TODAY()-BD11 -> 270
B12: =CONCATENATE(I12,K12,L12) -> 900122 | C12: =CONCATENATE(I12,K12) -> 90012 | D12: 22526 | E12: 4-Ipaussu | F12: 61 | G12: Ipau | H12: 71 | I12: 9001 | J12: FAZENDA SANTA HELENA | K12: 2 | L12: 2 | M12: 6 | O12: 15.85 | P12: 0 | Q12: RB966928 | R12: Super Precoce | S12: 4 | T12: 3o. Corte | U12: 1 | V12: 44540 | W12: 355 | X12: N | Y12: N | AB12: N | AC12: S | AD12: N | AE12: N | AF12: N | AG12: 2 | AH12: 0 | AI12: 7 | AJ12: 0 | AK12: 61 | AL12: mC | AM12: 0,9 x 1,5-Alternado | AN12: 15.85 | AO12: 90.58 | AP12: 1435.693 | AQ12: 15.85 | AR12: 81.07 | AS12: 1284.9595 | BC12: Fechado | BD12: 45853 | BE12: 1267.27 | BF12: Propria | BG12: RAIZEN ENERGIA S/A - FILIAL IPAUSSU | BH12: =TODAY()-BD12 -> 270
B13: =CONCATENATE(I13,K13,L13) -> 900123 | C13: =CONCATENATE(I13,K13) -> 90012 | D13: 22526 | E13: 4-Ipaussu | F13: 61 | G13: Ipau | H13: 71 | I13: 9001 | J13: FAZENDA SANTA HELENA | K13: 2 | L13: 3 | M13: 6 | O13: 2.47 | P13: 0 | Q13: RB966928 | R13: Super Precoce | S13: 4 | T13: 3o. Corte | U13: 1 | V13: 44540 | W13: 355 | X13: N | Y13: N | AB13: N | AC13: S | AD13: N | AE13: N | AF13: N | AG13: 2 | AH13: 0 | AI13: 7 | AJ13: 0 | AK13: 61 | AL13: mC | AM13: 0,9 x 1,5-Alternado | AN13: 2.47 | AO13: 90.58 | AP13: 223.7326 | AQ13: 2.47 | AR13: 81.07 | AS13: 200.2429 | BC13: Fechado | BD13: 45853 | BE13: 37.57 | BF13: Propria | BG13: RAIZEN ENERGIA S/A - FILIAL IPAUSSU | BH13: =TODAY()-BD13 -> 270
B14: =CONCATENATE(I14,K14,L14) -> 900124 | C14: =CONCATENATE(I14,K14) -> 90012 | D14: 22526 | E14: 4-Ipaussu | F14: 61 | G14: Ipau | H14: 71 | I14: 9001 | J14: FAZENDA SANTA HELENA | K14: 2 | L14: 4 | M14: 6 | O14: 3.73 | P14: 0 | Q14: RB966928 | R14: Super Precoce | S14: 4 | T14: 3o. Corte | U14: 1 | V14: 44540 | W14: 355 | X14: N | Y14: N | AB14: N | AC14: S | AD14: N | AE14: N | AF14: N | AG14: 2 | AH14: 0 | AI14: 7 | AJ14: 0 | AK14: 61 | AL14: mC | AM14: 0,9 x 1,5-Alternado | AN14: 3.73 | AO14: 90.58 | AP14: 337.8634 | AQ14: 3.73 | AR14: 81.07 | AS14: 302.3911 | BC14: Fechado | BD14: 45853 | BE14: 352.86 | BF14: Propria | BG14: RAIZEN ENERGIA S/A - FILIAL IPAUSSU | BH14: =TODAY()-BD14 -> 270
B15: =CONCATENATE(I15,K15,L15) -> 900125 | C15: =CONCATENATE(I15,K15) -> 90012 | D15: 22526 | E15: 4-Ipaussu | F15: 61 | G15: Ipau | H15: 71 | I15: 9001 | J15: FAZENDA SANTA HELENA | K15: 2 | L15: 5 | M15: 6 | O15: 4.79 | P15: 0 | Q15: RB966928 | R15: Super Precoce | S15: 4 | T15: 3o. Corte | U15: 1 | V15: 44540 | W15: 355 | X15: N | Y15: N | AB15: N | AC15: S | AD15: N | AE15: N | AF15: N | AG15: 2 | AH15: 0 | AI15: 7 | AJ15: 0 | AK15: 61 | AL15: mC | AM15: 0,9 x 1,5-Alternado | AN15: 4.79 | AO15: 90.58 | AP15: 433.8782 | AQ15: 4.79 | AR15: 81.07 | AS15: 388.3253 | BC15: Fechado | BD15: 45853 | BE15: 461.07 | BF15: Propria | BG15: RAIZEN ENERGIA S/A - FILIAL IPAUSSU | BH15: =TODAY()-BD15 -> 270
B16: =CONCATENATE(I16,K16,L16) -> 900126 | C16: =CONCATENATE(I16,K16) -> 90012 | D16: 22526 | E16: 4-Ipaussu | F16: 61 | G16: Ipau | H16: 71 | I16: 9001 | J16: FAZENDA SANTA HELENA | K16: 2 | L16: 6 | M16: 6 | O16: 3.78 | P16: 0 | Q16: RB966928 | R16: Super Precoce | S16: 4 | T16: 3o. Corte | U16: 1 | V16: 44540 | W16: 355 | X16: N | Y16: N | AB16: N | AC16: S | AD16: N | AE16: N | AF16: N | AG16: 2 | AH16: 0 | AI16: 7 | AJ16: 0 | AK16: 61 | AL16: mC | AM16: 0,9 x 1,5-Alternado | AN16: 3.78 | AO16: 90.58 | AP16: 342.3924 | AQ16: 3.78 | AR16: 81.07 | AS16: 306.4446 | BC16: Fechado | BD16: 45853 | BE16: 418.23 | BF16: Propria | BG16: RAIZEN ENERGIA S/A - FILIAL IPAUSSU | BH16: =TODAY()-BD16 -> 270
B17: =CONCATENATE(I17,K17,L17) -> 900127 | C17: =CONCATENATE(I17,K17) -> 90012 | D17: 22526 | E17: 4-Ipaussu | F17: 61 | G17: Ipau | H17: 71 | I17: 9001 | J17: FAZENDA SANTA HELENA | K17: 2 | L17: 7 | M17: 6 | O17: 5.92 | P17: 0 | Q17: RB966928 | R17: Super Precoce | S17: 4 | T17: 3o. Corte | U17: 1 | V17: 44540 | W17: 355 | X17: N | Y17: N | AB17: N | AC17: S | AD17: N | AE17: N | AF17: N | AG17: 2 | AH17: 0 | AI17: 7 | AJ17: 0 | AK17: 61 | AL17: mA | AM17: 0,9 x 1,5-Alternado | AN17: 5.92 | AO17: 90.58 | AP17: 536.2336 | AQ17: 5.92 | AR17: 81.07 | AS17: 479.9344 | BC17: Fechado | BD17: 45853 | BE17: 457.86 | BF17: Propria | BG17: RAIZEN ENERGIA S/A - FILIAL IPAUSSU | BH17: =TODAY()-BD17 -> 270
B18: =CONCATENATE(I18,K18,L18) -> 900128 | C18: =CONCATENATE(I18,K18) -> 90012 | D18: 22526 | E18: 4-Ipaussu | F18: 61 | G18: Ipau | H18: 71 | I18: 9001 | J18: FAZENDA SANTA HELENA | K18: 2 | L18: 8 | M18: 1 | N18: 1 | O18: 9.82 | P18: 0 | Q18: CTC4 | R18: Super Precoce | S18: 9 | T18: 8o. Corte | U18: 1 | V18: 42940 | W18: 354 | X18: N | Y18: S | Z18: 18 Meses | AA18: MPB Manual | AB18: N | AC18: N | AD18: N | AE18: N | AF18: N | AG18: 2 | AH18: 0 | AI18: 5 | AJ18: 0 | AK18: 61 | AL18: mC | AM18: 0,9 x 1,5-Alternado | AN18: 9.82 | AO18: 52.22 | AP18: 512.8004 | AQ18: 9.82 | AR18: 40.07 | AS18: 393.4874 | BC18: Fechado | BD18: 45779 | BE18: 366.34 | BF18: Propria | BG18: RAIZEN ENERGIA S/A - FILIAL IPAUSSU | BH18: =TODAY()-BD18 -> 344
B19: =CONCATENATE(I19,K19,L19) -> 900129 | C19: =CONCATENATE(I19,K19) -> 90012 | D19: 22526 | E19: 4-Ipaussu | F19: 61 | G19: Ipau | H19: 71 | I19: 9001 | J19: FAZENDA SANTA HELENA | K19: 2 | L19: 9 | M19: 1 | N19: 1 | O19: 0.34 | P19: 0 | Q19: SP80-3280 | R19: Super Precoce | S19: 9 | T19: 8o. Corte | U19: 1 | V19: 42940 | W19: 354 | X19: N | Y19: S | Z19: 18 Meses | AA19: MPB Manual | AB19: N | AC19: N | AD19: N | AE19: N | AF19: N | AG19: 2 | AH19: 0 | AI19: 5 | AJ19: 0 | AK19: 61 | AL19: mB | AM19: 0,9 x 1,5-Alternado | AN19: 0.34 | AO19: 52.22 | AP19: 17.7548 | AQ19: 0.34 | AR19: 40.07 | AS19: 13.6238 | BC19: Fechado | BD19: 45779 | BF19: Propria | BG19: RAIZEN ENERGIA S/A - FILIAL IPAUSSU | BH19: =TODAY()-BD19 -> 344
B20: =CONCATENATE(I20,K20,L20) -> 9001210 | C20: =CONCATENATE(I20,K20) -> 90012 | D20: 22526 | E20: 4-Ipaussu | F20: 61 | G20: Ipau | H20: 71 | I20: 9001 | J20: FAZENDA SANTA HELENA | K20: 2 | L20: 10 | M20: 4 | O20: 25.28 | P20: 0 | Q20: CTC9005 | R20: Super Precoce | S20: 6 | T20: 5o. Corte | U20: 1 | V20: 44117 | W20: 350 | X20: N | Y20: N | AB20: N | AC20: S | AD20: N | AE20: N | AF20: N | AG20: 2 | AH20: 0 | AI20: 7 | AJ20: 0 | AK20: 61 | AL20: mB | AM20: 0,9 x 1,5-Alternado | AN20: 25.28 | AO20: 66.4 | AP20: 1678.592 | AQ20: 25.28 | AR20: 67.07 | AS20: 1695.5296 | BC20: Fechado | BD20: 45853 | BE20: 1873.15 | BF20: Propria | BG20: RAIZEN ENERGIA S/A - FILIAL IPAUSSU | BH20: =TODAY()-BD20 -> 270
