Workbook

Sheet Dashboard
A1: DASHBOARD CCT - ÁRVORE DE DECISÃO TCD
A2: META TCD: | B2: ='KPI por frente'!H3 -> 10091.25 | C2: REAL TCD: | D2: ='KPI por frente'!I3 -> 5557.74 | E2: % ATING: | F2: =IFERROR(D2/B2,0) -> 0.55074842 | G2: BATEU? | H2: =IF(D2>=B2,"SIM","NÃO") -> NÃO
A4: INDICADOR | B4: ÁREA | C4: META TOTAL | D4: REAL TOTAL | E4: % ATING | F4: STATUS
A5: Moagem [ton] | B5: TCD | C5: ='KPI por frente'!H3 -> 10091.25 | D5: ='KPI por frente'!I3 -> 5557.74 | E5: =IFERROR(D5/C5,0) -> 0.55074842 | F5: =IF(D5>=C5,"OK","OFENSOR") -> OFENSOR
A6: Densidade [ton/viag] | B6: Transporte | C6: ='KPI por frente'!H7 -> 33.5 | D6: ='KPI por frente'!I7 -> 34.120508 | E6: =IFERROR(D6/C6,0) -> 1.0185226 | F6: =IF(D6>=C6,"OK","OFENSOR") -> OK
A7: Prod. Colhedora [ton/maq/dia] | B7: Corte | C7: ='KPI por frente'!H8 -> 756.77335 | D7: ='KPI por frente'!I8 -> 783.04319 | E7: =IFERROR(D7/C7,0) -> 1.0347129 | F7: =IF(D7>=C7,"OK","OFENSOR") -> OK
A8: Vel. Colheita [km/h] | B8: Corte | C8: ='KPI por frente'!H11 -> 3.9798845 | D8: ='KPI por frente'!I11 -> 4.7187304 | E8: =IFERROR(D8/C8,0) -> 1.185645 | F8: =IF(D8>=C8,"OK","OFENSOR") -> OK
A9: Manobra [%] | B9: Corte | C9: ='KPI por frente'!H12 -> 16.735341 | D9: ='KPI por frente'!I12 -> 22.216802 | E9: =IFERROR(D9/C9,0) -> 1.3275381 | F9: =IF(D9<=C9,"OK","OFENSOR") -> OFENSOR
A10: NSO [%] | B10: Corte | C10: ='KPI por frente'!H13 -> 82.150383 | D10: ='KPI por frente'!I13 -> 86.643993 | E10: =IFERROR(D10/C10,0) -> 1.0546998 | F10: =IF(D10>=C10,"OK","OFENSOR") -> OK
A11: Disp. Colhedora [%] | B11: Corte | C11: ='KPI por frente'!H14 -> 87 | D11: ='KPI por frente'!I14 -> 87.549679 | E11: =IFERROR(D11/C11,0) -> 1.0063181 | F11: =IF(D11>=C11,"OK","OFENSOR") -> OK
A12: NS Transbordo [%] | B12: Carregamento | C12: ='KPI por frente'!H18 -> 87 | D12: ='KPI por frente'!I18 -> 91.597469 | E12: =IFERROR(D12/C12,0) -> 1.0528445 | F12: =IF(D12>=C12,"OK","OFENSOR") -> OK
A13: Vel. Transb. Vazio [km/h] | B13: Carregamento | C13: ='KPI por frente'!H19 -> 97 | D13: ='KPI por frente'!I19 -> 91.466565 | E13: =IFERROR(D13/C13,0) -> 0.94295428 | F13: =IF(D13>=C13,"OK","OFENSOR") -> OFENSOR
A14: Vel. Transb. Carreg. [km/h] | B14: Carregamento | C14: ='KPI por frente'!H20 -> 12.201245 | D14: ='KPI por frente'!I20 -> 13.810615 | E14: =IFERROR(D14/C14,0) -> 1.1319022 | F14: =IF(D14>=C14,"OK","OFENSOR") -> OK
A15: Disp. Transbordo [%] | B15: Carregamento | C15: ='KPI por frente'!H21 -> 11.237142 | D15: ='KPI por frente'!I21 -> 11.08027 | E15: =IFERROR(D15/C15,0) -> 0.98603981 | F15: =IF(D15>=C15,"OK","OFENSOR") -> OFENSOR
A16: T2 [min] | B16: Carregamento | C16: ='KPI por frente'!H24 -> 97 | D16: ='KPI por frente'!I24 -> 99.939611 | E16: =IFERROR(D16/C16,0) -> 1.0303053 | F16: =IF(D16<=C16,"OK","OFENSOR") -> OFENSOR
A17: NS Caminhão [%] | B17: Transporte | C17: ='KPI por frente'!H23 -> 75 | D17: ='KPI por frente'!I23 -> 84.023284 | E17: =IFERROR(D17/C17,0) -> 1.1203105 | F17: =IF(D17>=C17,"OK","OFENSOR") -> OK
A18: Raio [km] | B18: Transporte | C18: ='KPI por frente'!H25 -> 27 | D18: ='KPI por frente'!I25 -> 42.371528 | E18: =IFERROR(D18/C18,0) -> 1.5693158 | F18: =IF(D18<=C18,"OK","OFENSOR") -> OFENSOR
A19: Imp. Vegetal [%] | B19: Corte | C19: ='KPI por frente'!H26 -> 29.418587 | D19: ='KPI por frente'!I26 -> 41.403306 | E19: =IFERROR(D19/C19,0) -> 1.407386 | F19: =IF(D19<=C19,"OK","OFENSOR") -> OFENSOR
A20: Horas de Corte Efetivo [h/maq]

Sheet KPI por frente
A1: Frente | B1: 351 | D1: 352 | F1: 353 | H1: Total | J1: Responsabildade | L1: Aproveitamento ind | M1: 1 | N1: Meta dia | O1: 8400
A2: Indicador | B2: Meta | C2: Real | D2: Meta | E2: Real | F2: Meta | G2: Real | H2: Meta | I2: Real | J2: Resp | N2: Meta corrigida | O2: =O1*M1 -> 8400
A3: Moagem [ton] | B3: 2240 | C3: 1337.08 | D3: 3792.5 | E3: 870.24 | F3: 4058.75 | G3: 3350.42 | H3: 10091.25 | I3: 5557.74 | J3: TCD | N3: Meta corrigida por CD | O3: =O2/9 -> 933.33333
A4: Moagem Frente [ton] | B4: 2240 | C4: 1337.08 | D4: 3792.5 | E4: 870.24 | F4: 4058.75 | G4: 3350.42 | H4: 10091.25 | I4: 5557.74 | J4: -
A5: Projeção Dia [ton] | B5: 3584 | C5: 2582.5 | D5: 6068 | E5: 1434.54 | F5: 6494 | G5: 5590.94 | H5: 16146 | I5: 9607.98 | J5: -
A6: Realizado ult. 3h (Moagem) [ton] | B6: 149.33333 | C6: 59.793333 | D6: 252.83333 | E6: 21.2 | F6: 270.58333 | G6: 154.17333 | H6: 672.75 | I6: 235.16667 | J6: -
A7: Densidade [ton/viag] | B7: 33.5 | C7: 30.192095 | D7: 33.5 | E7: 31.178182 | F7: 33.5 | G7: 37.268 | H7: 33.5 | I7: 34.120508 | J7: Transporte
A8: Prod. Colhedora [ton/maq/dia] | B8: 856.85892 | C8: 603.72822 | D8: 445.39275 | E8: 309.85995 | F8: 1018.1112 | G8: 1640.68 | H8: 756.77335 | I8: 783.04319 | J8: corte
A9: Horas de Corte Efetivo [h/maq] | B9: 14.038085 | C9: 14.76078 | D9: 16.654491 | E9: 8.1100528 | F9: 16.654491 | G9: 13.064074 | H9: 15.958041 | I9: 11.771108 | J9: corte
A10: Horas de Corte Corrida [h/maq] | B10: 14.038085 | C10: 9.1829069 | D10: 16.654491 | E10: 6.4826374 | F10: 16.654491 | G10: 9.1371338 | H10: 15.958041 | I10: 8.2411323 | J10: -
A11: Vel. Colheita [km/h] | B11: 3.3518453 | C11: 5.0084354 | D11: 4.335223 | E11: 4.240155 | F11: 4.175557 | G11: 4.7051183 | H11: 3.9798845 | I11: 4.7187304 | J11: Corte
A12: Manobra [%] | B12: 16.735341 | C12: 20.078521 | D12: 16.735341 | E12: 30.348902 | F12: 16.735341 | G12: 16.978186 | H12: 16.735341 | I12: 22.216802 | J12: Corte
A13: NSO [%] | B13: 82.150383 | C13: 93.432669 | D13: 82.150383 | E13: 75.753135 | F13: 82.150383 | G13: 86.151483 | H13: 82.150383 | I13: 86.643993 | J13: Corte
A14: Disp. Colhedora [%] | B14: 87 | C14: 100 | D14: 87 | E14: 74.31222 | F14: 87 | G14: 85.769869 | H14: 87 | I14: 87.549679 | J14: Corte
A15: Limitação Indústria [h/maq] | C15: 0.40298769 | E15: 3.0794444 | G15: 1.6489621 | I15: 1.4366688 | J15: -
A16: Chuva/Solo úmido [h/maq] | C16: 14.185486 | E16: 5.4910185 | G16: 8.53 | I16: 9.4021682 | J16: -
A17: Tempo Indeterminado [h/maq] | C17: 0.07483451 | E17: 0.27687926 | G17: 0.55133055 | J17: -
A18: RTK Colhedora [%] | B18: 87 | C18: 91.248687 | D18: 87 | E18: 86.274112 | F18: 87 | G18: 97.077879 | H18: 87 | I18: 91.597469 | J18: Carregamento
A19: NS Transbordo [%] | B19: 97 | C19: 88.07733 | D19: 97 | E19: 98.383873 | F19: 97 | G19: 92.654747 | H19: 97 | I19: 91.466565 | J19: Carregamento
A20: Vel. Transb. Vazio [km/h] | B20: 12.201245 | C20: 13.766194 | D20: 12.201245 | E20: 11.425061 | F20: 12.201245 | G20: 15.501776 | H20: 12.201245 | I20: 13.810615 | J20: Carregamento
A21: Vel. Transb. Carreg. [km/h] | B21: 11.237142 | C21: 12.290502 | D21: 11.237142 | E21: 9.2084675 | F21: 11.237142 | G21: 11.986981 | H21: 11.237142 | I21: 11.08027 | J21: Carregamento
A22: Disp. Transbordo [%] | B22: 88 | C22: 88.716578 | D22: 88 | E22: 99.276483 | F22: 88 | G22: 85.650384 | H22: 88 | I22: 91.697493 | J22: -
A23: RTK Transbordo [%] | B23: 75 | C23: 80.678922 | D23: 75 | E23: 75.293393 | F23: 75 | G23: 91.964675 | H23: 75 | I23: 84.023284 | J23: Transporte
A24: NS Caminhão [%] | B24: 97 | C24: 99.868789 | D24: 97 | E24: 100 | F24: 97 | G24: 100 | H24: 97 | I24: 99.939611 | J24: Carregamento
A25: T2 [min] | B25: 27 | C25: 47.9325 | D25: 27 | E25: 41.790278 | F25: 27 | G25: 38.952778 | H25: 27 | I25: 42.371528 | J25: Transporte
A26: Raio [km] | B26: 29.418587 | C26: 14.891056 | D26: 29.418587 | E26: 58.362829 | F26: 29.418587 | G26: 48.960411 | H26: 29.418587 | I26: 41.403306 | J26: Corte
A27: Imp. Vegetal [%] | C27: 11.67 | G27: 9.43 | I27: 10.437094 | J27: Corte
A28: ATR [kg/ton] | B28: 7.2763698 | C28: 91.550062 | D28: 52.003904 | E28: 66.847558 | F28: 121.18989 | G28: 127.17403 | H28: 78.192583 | I28: 108.14911 | J28: -
A29: Fibra [%] | C29: 13.308722 | E29: 11.609874 | G29: 13.668718 | I29: 13.247642 | J29: -
A30: Fibra [ton/carga] | C30: 4.0169387 | E30: 3.6186279 | G30: 5.0943815 | I30: 4.5196394 | J30: -
A31: Imp. Mineral [kg/ton] | C31: 4.61 | E31: 2.32 | G31: 36.67 | I31: 25.119374 | J31: Corte
A32: Hrs Efetivo [h] | C32: 28.37 | E32: 17.215 | G32: 20.405 | I32: 40.805 | J32: -
A33: Hrs Despontador [h] | C33: 24.825 | E33: 15.17 | G33: 18.04 | I33: 58.035 | J33: -
A34: Despontador [%] | C34: 87.298695 | E34: 88.119669 | G34: 88.727498 | I34: 87.918911
A35: Extrator Primário [RPM] | C35: 691.76651 | E35: 706.54635 | G35: 757.92702 | I35: 715.947

Sheet Base de tempo
A1: INSTANCIA | B1: DATA CONSIDERADA | C1: EQUIPAMENTO | D1: FRENTE | E1: FAZENDA | F1: PARTIDA_USINA | G1: CHEGADA LAVOURA | H1: SAIDA LAVOURA | I1: CHEGADA PATIO | J1: FIM CICLO | K1: t1 | L1: t2 | M1: t3 | N1: t4 | O1: Max T2 | P1: Considerar T2 | Q1: Max T4 | R1: Considerar T4 | S1: OPL
A2: IPA | B2: 46121 | C2: 8013478 | D2: 352 | E2: 19817 | F2: 46118.692 | G2: 46121.639 | H2: 46123.45 | I2: 46123.873 | J2: 46123.919 | K2: 4243.0667 | L2: 2608.3167 | M2: 608.48333 | N2: 65.75 | O2: 90 | Q2: 105 | R2: Sim | S2: RITMO
A3: IPA | B3: 46117 | C3: 8013468 | D3: 352 | E3: 19817 | F3: 46117.923 | G3: 46117.983 | H3: 46118.497 | I3: 46118.588 | J3: 46119.78 | K3: 85.9 | L3: 739.65 | M3: 131.73333 | N3: 1716.45 | O3: 90 | Q3: 105 | S3: RITMO
A4: IPA | B4: 46117 | C4: 8013482 | D4: 352 | E4: 19817 | F4: 46117.789 | G4: 46117.847 | H4: 46118.3 | I4: 46118.692 | J4: 46123.852 | K4: 84.416667 | L4: 652.01667 | M4: 563.85 | N4: 7430.6333 | O4: 90 | Q4: 105 | S4: RITMO
A5: IPA | B5: 46117 | C5: 8013484 | D5: 352 | E5: 19817 | F5: 46117.745 | G5: 46117.801 | H5: 46118.192 | I5: 46118.403 | J5: 46119.945 | K5: 81.15 | L5: 563.33333 | M5: 303 | N5: 2220.5833 | O5: 90 | Q5: 105 | S5: RITMO
A6: IPA | B6: 46117 | C6: 8013472 | D6: 353 | E6: 19461 | F6: 46117.902 | G6: 46117.972 | H6: 46118.232 | I6: 46118.324 | J6: 46118.542 | K6: 99.75 | L6: 374.66667 | M6: 133.48333 | N6: 313.06667 | O6: 90 | Q6: 105 | S6: RITMO
A7: IPA | B7: 46117 | C7: 8013473 | D7: 352 | E7: 19817 | F7: 46117.732 | G7: 46117.8 | H7: 46118.011 | I7: 46118.201 | J7: 46118.246 | K7: 98.383333 | L7: 302.73333 | M7: 274.03333 | N7: 64.216667 | O7: 90 | Q7: 105 | R7: Sim | S7: RITMO
A8: IPA | B8: 46117 | C8: 8013462 | D8: 351 | E8: 9126 | F8: 46117.673 | G8: 46117.709 | H8: 46117.849 | I8: 46117.863 | J8: 46117.863 | K8: 52 | L8: 201.73333 | M8: 19.8 | N8: 0.68333333 | O8: 90 | Q8: 105 | S8: RITMO
A9: IPA | B9: 46117 | C9: 8013475 | D9: 351 | E9: 19679 | F9: 46117.8 | G9: 46117.844 | H9: 46117.983 | I9: 46118.014 | J9: 46118.172 | K9: 63.166667 | L9: 199.5 | M9: 44.25 | N9: 228.23333 | O9: 90 | Q9: 105 | S9: RITMO
A10: IPA | B10: 46124 | C10: 8013462 | D10: 352 | E10: 19817 | F10: 46124.631 | G10: 46124.679 | H10: 46124.811 | I10: 46124.822 | J10: 46124.958 | K10: 70.033333 | L10: 189.65 | M10: 15.7 | N10: 195.36667 | O10: 90 | Q10: 105 | S10: RITMO
A11: IPA | B11: 46119 | C11: 8013470 | D11: 353 | E11: 19461 | F11: 46119.793 | G11: 46119.85 | H11: 46119.971 | I11: 46120.042 | J11: 46123.694 | K11: 82.566667 | L11: 174.21667 | M11: 101.76667 | N11: 5258.6667 | O11: 90 | Q11: 105 | S11: RITMO
A12: IPA | B12: 46123 | C12: 8013468 | D12: 351 | E12: 9143 | F12: 46123.891 | G12: 46123.908 | H12: 46124.015 | I12: 46124.037 | J12: 46124.381 | K12: 23.516667 | L12: 154.65 | M12: 31.183333 | N12: 495.71667 | O12: 90 | Q12: 105 | S12: RITMO
A13: IPA | B13: 46123 | C13: 8013473 | D13: 351 | E13: 9143 | F13: 46123.816 | G13: 46123.833 | H13: 46123.94 | I13: 46123.973 | J13: 46124.331 | K13: 25.05 | L13: 153.88333 | M13: 47.833333 | N13: 515.48333 | O13: 90 | Q13: 105 | S13: RITMO
A14: IPA | B14: 46117 | C14: 8013470 | D14: 353 | E14: 19461 | F14: 46117.92 | G14: 46117.977 | H14: 46118.076 | I14: 46118.163 | J14: 46118.37 | K14: 83.166667 | L14: 142.05 | M14: 125.06667 | N14: 297.85 | O14: 90 | Q14: 105 | S14: RITMO
A15: IPA | B15: 46117 | C15: 8013460 | D15: 351 | E15: 19679 | F15: 46117.595 | G15: 46117.623 | H15: 46117.713 | I15: 46117.74 | J15: 46117.741 | K15: 40.8 | L15: 128.73333 | M15: 39.5 | N15: 0.38333333 | O15: 90 | Q15: 105 | S15: RITMO
A16: IPA | B16: 46119 | C16: 8013481 | D16: 353 | E16: 19461 | F16: 46119.889 | G16: 46119.947 | H16: 46120.034 | I16: 46120.404 | J16: 46123.757 | K16: 83.166667 | L16: 124.4 | M16: 533.41667 | N16: 4827.8333 | O16: 90 | Q16: 105 | S16: RITMO
A17: IPA | B17: 46124 | C17: 8013475 | D17: 351 | E17: 9143 | F17: 46124.712 | G17: 46124.733 | H17: 46124.817 | I17: 46124.862 | J17: 46125.041 | K17: 30.616667 | L17: 121.1 | M17: 63.95 | N17: 258.98333 | O17: 90 | Q17: 105 | S17: RITMO
A18: IPA | B18: 46118 | C18: 8013478 | D18: 353 | E18: 19461 | F18: 46117.984 | G18: 46118.036 | H18: 46118.114 | I18: 46118.202 | J18: 46118.692 | K18: 74.966667 | L18: 112.55 | M18: 126.68333 | N18: 705.26667 | O18: 90 | Q18: 105 | S18: RITMO
A19: IPA | B19: 46118 | C19: 8013476 | D19: 351 | E19: 19679 | F19: 46118.405 | G19: 46118.431 | H19: 46118.504 | I19: 46118.532 | J19: 46119.846 | K19: 37.4 | L19: 105.68333 | M19: 40.666667 | N19: 1892.2667 | O19: 90 | Q19: 105 | S19: RITMO
... A23: IPA | B23: 46124 | C23: 8013469 | D23: 351 | E23: 9143 | F23: 46124.457 | G23: 46124.48 | H23: 46124.544 | I23: 46124.583 | J23: 46124.708 | K23: 33.25 | L23: 91.366667 | M23: 56.066667 | N23: 180.36667 | O23: 90 | Q23: 105 | S23: RITMO
A24: IPA | B24: 46124 | C24: 8013470 | D24: 352 | E24: 19817 | F24: 46124.877 | G24: 46124.946 | H24: 46125.008 | I24: 46125.084 | K24: 99.383333 | L24: 89.35 | M24: 108.98333 | O24: 90 | P24: Sim | Q24: 105 | S24: RITMO
A25: IPA | B25: 46124 | C25: 8013468 | D25: 351 | E25: 9143 | F25: 46124.786 | G25: 46124.807 | H25: 46124.866 | I25: 46124.94 | J25: 46125.054 | K25: 30.266667 | L25: 84.783333 | M25: 106.91667 | N25: 164.1 | O25: 90 | P25: Sim | Q25: 105 | S25: RITMO
A26: IPA | B26: 46120 | C26: 8013484 | D26: 353 | E26: 19461 | F26: 46119.946 | G26: 46120.001 | H26: 46120.057 | I26: 46122.144 | J26: 46123.72 | K26: 79.933333 | L26: 81.016667 | M26: 3005.1167 | N26: 2269.1167 | O26: 90 | P26: Sim | Q26: 105 | S26: RITMO
A27: IPA | B27: 46124 | C27: 8013478 | D27: 351 | E27: 9143 | F27: 46124.847 | G27: 46124.863 | H27: 46124.917 | I27: 46124.946 | J27: 46125.067 | K27: 24.416667 | L27: 77.033333 | M27: 42.466667 | N27: 174.2 | O27: 90 | P27: Sim | Q27: 105 | S27: RITMO
A28: IPA | B28: 46117 | C28: 8013468 | D28: 351 | E28: 19679 | F28: 46117.643 | G28: 46117.677 | H28: 46117.729 | I28: 46117.923 | J28: 46117.923 | K28: 48.85 | L28: 75.916667 | M28: 278.78333 | N28: -0.38333333 | O28: 90 | P28: Sim | Q28: 105 | S28: RITMO
A29: IPA | B29: 46118 | C29: 8013462 | D29: 353 | E29: 19461 | F29: 46118.143 | G29: 46118.203 | H29: 46118.253 | I29: 46118.326 | J29: 46118.736 | K29: 85.816667 | L29: 72.533333 | M29: 105.33333 | N29: 590.76667 | O29: 90 | P29: Sim | Q29: 105 | S29: RITMO
A30: IPA | B30: 46124 | C30: 8013477 | D30: 353 | E30: 19461 | F30: 46124.849 | G30: 46124.902 | H30: 46124.952 | I30: 46125.052 | K30: 77.25 | L30: 70.766667 | M30: 144.98333 | O30: 90 | P30: Sim | Q30: 105 | S30: RITMO
A31: IPA | B31: 46124 | C31: 8013474 | D31: 353 | E31: 19461 | F31: 46124.821 | G31: 46124.875 | H31: 46124.922 | I31: 46125.024 | J31: 46125.077 | K31: 77.933333 | L31: 67.033333 | M31: 147.63333 | N31: 75.116667 | O31: 90 | P31: Sim | Q31: 105 | R31: Sim | S31: RITMO
A32: IPA | B32: 46124 | C32: 8013470 | D32: 352 | E32: 19817 | F32: 46124.561 | G32: 46124.611 | H32: 46124.655 | I32: 46124.715 | J32: 46124.876 | K32: 72.233333 | L32: 62.883333 | M32: 86.1 | N32: 232.68333 | O32: 90 | P32: Sim | Q32: 105 | S32: RITMO
A33: IPA | B33: 46124 | C33: 8013463 | D33: 353 | E33: 19461 | F33: 46124.612 | G33: 46124.663 | H33: 46124.703 | I33: 46124.78 | J33: 46124.936 | K33: 73.583333 | L33: 57.116667 | M33: 111.23333 | N33: 225.03333 | O33: 90 | P33: Sim | Q33: 105 | S33: RITMO
A34: IPA | B34: 46124 | C34: 8013483 | D34: 353 | E34: 19461 | F34: 46124.747 | G34: 46124.801 | H34: 46124.837 | I34: 46124.929 | J34: 46125.035 | K34: 77.283333 | L34: 51.833333 | M34: 132.65 | N34: 153.38333 | O34: 90 | P34: Sim | Q34: 105 | S34: RITMO
A35: IPA | B35: 46118 | C35: 8013463 | D35: 353 | E35: 19461 | F35: 46118.365 | G35: 46118.412 | H35: 46118.448 | I35: 46118.547 | J35: 46118.819 | K35: 67.733333 | L35: 50.883333 | M35: 143.1 | N35: 391.7 | O35: 90 | P35: Sim | Q35: 105 | S35: RITMO
A36: IPA | B36: 46117 | C36: 8013462 | D36: 353 | E36: 19461 | F36: 46117.864 | G36: 46117.923 | H36: 46117.958 | I36: 46118.042 | J36: 46118.142 | K36: 85.6 | L36: 49.85 | M36: 120.96667 | N36: 144.8 | O36: 90 | P36: Sim | Q36: 105 | S36: RITMO
A37: IPA | B37: 46124 | C37: 8013484 | D37: 353 | E37: 19461 | F37: 46124.703 | G37: 46124.759 | H37: 46124.793 | I37: 46124.88 | J37: 46125.08 | K37: 79.95 | L37: 49.716667 | M37: 125.35 | N37: 288.18333 | O37: 90 | P37: Sim | Q37: 105 | S37: RITMO
A38: IPA | B38: 46118 | C38: 8013475 | D38: 353 | E38: 19461 | F38: 46118.173 | G38: 46118.229 | H38: 46118.263 | I38: 46118.884 | J38: 46119.571 | K38: 80.55 | L38: 49.266667 | M38: 894.55 | N38: 989.28333 | O38: 90 | P38: Sim | Q38: 105 | S38: RITMO
A39: IPA | B39: 46124 | C39: 8013467 | D39: 353 | E39: 19461 | F39: 46124.669 | G39: 46124.725 | H39: 46124.759 | I39: 46124.851 | J39: 46124.998 | K39: 80.833333 | L39: 48.983333 | M39: 132.33333 | N39: 211.81667 | O39: 90 | P39: Sim | Q39: 105 | S39: RITMO
A40: IPA | B40: 46124 | C40: 8013482 | D40: 353 | E40: 19461 | F40: 46124.788 | G40: 46124.862 | H40: 46124.895 | I40: 46125.1 | K40: 106.7 | L40: 47.883333 | M40: 295.11667 | O40: 90 | P40: Sim | Q40: 105 | S40: RITMO
A41: IPA | B41: 46124 | C41: 8013472 | D41: 353 | E41: 19461 | F41: 46124.646 | G41: 46124.695 | H41: 46124.727 | I41: 46124.898 | J41: 46125.005 | K41: 70.45 | L41: 47.316667 | M41: 245.03333 | N41: 154.88333 | O41: 90 | P41: Sim | Q41: 105 | S41: RITMO
A42: IPA | B42: 46123 | C42: 8013465 | D42: 353 | E42: 19461 | F42: 46123.766 | G42: 46123.817 | H42: 46123.849 | I42: 46123.938 | J42: 46124.453 | K42: 72.85 | L42: 46.283333 | M42: 128.23333 | N42: 740.8 | O42: 90 | P42: Sim | Q42: 105 | S42: RITMO
A43: IPA | B43: 46123 | C43: 8013476 | D43: 353 | E43: 19461 | F43: 46123.74 | G43: 46123.799 | H43: 46123.828 | I43: 46123.917 | J43: 46124.66 | K43: 83.883333 | L43: 42.783333 | M43: 127.41667 | N43: 1069.5833 | O43: 90 | P43: Sim | Q43: 105 | S43: RITMO
...

Sheet Base cargas
A1: UNIDADE | B1: UNIDADE CADASTRO | C1: DT_MOVIMENTO | D1: HR_GUARITA | E1: CD_UNID_IND | F1: CD_FREN_TRAN | G1: CD_EQUIPAMENTO | H1: QT_LIQUIDO | I1: QT_BRUTO | J1: QTD CARGAS | K1: POND_DIST | L1: PROPRIEDADE | M1: OPL | N1: TIPO
A2: IPA | B2: IPA | C2: 46124 | D2: 46123.838 | E2: 61 | F2: 353 | G2: 8013468 | H2: 79380 | I2: 114040 | J2: 2 | K2: 3889620 | L2: RITMO LOGISTICA S/A | M2: RITMO | N2: Cana Propria
A3: IPA | B3: IPA | C3: 46124 | D3: 46123.862 | E3: 61 | F3: 353 | G3: 8013470 | H3: 78840 | I3: 113580 | J3: 2 | K3: 3863160 | L3: RITMO LOGISTICA S/A | M3: RITMO | N3: Cana Propria
A4: IPA | B4: IPA | C4: 46124 | D4: 46123.759 | E4: 61 | F4: 353 | G4: 8013469 | H4: 77860 | I4: 112500 | J4: 2 | K4: 3815140 | L4: RITMO LOGISTICA S/A | M4: RITMO | N4: Cana Propria
A5: IPA | B5: IPA | C5: 46119 | D5: 46118.996 | E5: 61 | F5: 353 | G5: 8013463 | H5: 76020 | I5: 110620 | J5: 2 | K5: 3801000 | L5: RITMO LOGISTICA S/A | M5: RITMO | N5: Cana Propria
A6: IPA | B6: IPA | C6: 46119 | D6: 46119.764 | E6: 61 | F6: 353 | G6: 8013485 | H6: 76760 | I6: 111800 | J6: 2 | K6: 3761240 | L6: RITMO LOGISTICA S/A | M6: RITMO | N6: Cana Propria
A7: IPA | B7: IPA | C7: 46119 | D7: 46119.76 | E7: 61 | F7: 353 | G7: 8013461 | H7: 76700 | I7: 112820 | J7: 2 | K7: 3758300 | L7: RITMO LOGISTICA S/A | M7: RITMO | N7: Cana Propria
A8: IPA | B8: IPA | C8: 46124 | D8: 46123.886 | E8: 61 | F8: 353 | G8: 8013485 | H8: 76660 | I8: 113720 | J8: 2 | K8: 3756340 | L8: RITMO LOGISTICA S/A | M8: RITMO | N8: Cana Propria
A9: IPA | B9: IPA | C9: 46124 | D9: 46119.96 | E9: 61 | F9: 353 | G9: 8013465 | H9: 77620 | I9: 112620 | J9: 2 | K9: 3749046 | L9: RITMO LOGISTICA S/A | M9: RITMO | N9: Cana Propria
A10: IPA | B10: IPA | C10: 46119 | D10: 46118.324 | E10: 61 | F10: 353 | G10: 8013472 | H10: 74880 | I10: 110080 | J10: 2 | K10: 3744000 | L10: RITMO LOGISTICA S/A | M10: RITMO | N10: Cana Propria
A11: IPA | B11: IPA | C11: 46124 | D11: 46123.76 | E11: 61 | F11: 353 | G11: 8013472 | H11: 76040 | I11: 110160 | J11: 2 | K11: 3725960 | L11: RITMO LOGISTICA S/A | M11: RITMO | N11: Cana Propria
A12: IPA | B12: IPA | C12: 46124 | D12: 46123.98 | E12: 61 | F12: 353 | G12: 8013465 | H12: 75760 | I12: 110460 | J12: 2 | K12: 3712240 | L12: RITMO LOGISTICA S/A | M12: RITMO | N12: Cana Propria
A13: IPA | B13: IPA | C13: 46119 | D13: 46119.797 | E13: 61 | F13: 353 | G13: 8013477 | H13: 75500 | I13: 110320 | J13: 2 | K13: 3699500 | L13: RITMO LOGISTICA S/A | M13: RITMO | N13: Cana Propria
... A67: IPA | B67: IPA | C67: 46124 | D67: 46123.543 | E67: 61 | F67: 351 | G67: 8013462 | H67: 65280 | I67: 99700 | J67: 2 | K67: 587520 | L67: RITMO LOGISTICA S/A | M67: RITMO | N67: Cana Propria

Sheet Base bordo
A1: DESC_UNIDADE | B1: DT_MOVIMENTO | C1: CD_EQUIPAMENTO | D1: DESC_GRUPO_EQUIPAMENTO | E1: CD_OPERACAO | F1: DESC_OPERAC | G1: TEMPO OPERAÇÃO | H1: VEL_POND | I1: HR_OPERACIONAIS_VEL | J1: MOTOR_LIGADO | K1: TRANSPORTADORA
A2: IPAUSSU | B2: 46124 | C2: 8013470 | D2: IPA-LN-000 | E2: 881 | F2: DESLOCAMENTO CARREGADO | G2: 6.3111111 | H2: 649243.22 | I2: 22720 | J2: 22720 | K2: RITMO LOGISTICA S/A
A3: IPAUSSU | B3: 46117 | C3: 8013461 | D3: IPA-LN-000 | E3: 895 | F3: DESLOCAMENTO VAZIO | G3: 4.0352778 | H3: 619414.36 | I3: 14527 | J3: 14527 | K3: RITMO LOGISTICA S/A
A4: IPAUSSU | B4: 46117 | C4: 8013460 | D4: IPA-LN-000 | E4: 895 | F4: DESLOCAMENTO VAZIO | G4: 5.2069444 | H4: 595925.09 | I4: 18745 | J4: 18745 | K4: RITMO LOGISTICA S/A
A5: IPAUSSU | B5: 46117 | C5: 8013470 | D5: IPA-LN-000 | E5: 895 | F5: DESLOCAMENTO VAZIO | G5: 5.2283333 | H5: 586699.79 | I5: 18822 | J5: 18822 | K5: RITMO LOGISTICA S/A
A6: IPAUSSU | B6: 46124 | C6: 8013474 | D6: IPA-LN-000 | E6: 895 | F6: DESLOCAMENTO VAZIO | G6: 4.3047222 | H6: 535356.59 | I6: 15497 | J6: 15497 | K6: RITMO LOGISTICA S/A
A7: IPAUSSU | B7: 46124 | C7: 8013483 | D7: IPA-LN-000 | E7: 881 | F7: DESLOCAMENTO CARREGADO | G7: 5.7730556 | H7: 519150.98 | I7: 20783 | J7: 20783 | K7: RITMO LOGISTICA S/A
A8: IPAUSSU | B8: 46124 | C8: 8013474 | D8: IPA-LN-000 | E8: 881 | F8: DESLOCAMENTO CARREGADO | G8: 5.575 | H8: 488002.63 | I8: 20070 | J8: 20070 | K8: RITMO LOGISTICA S/A
A9: IPAUSSU | B9: 46124 | C9: 8013473 | D9: IPA-LN-000 | E9: 895 | F9: DESLOCAMENTO VAZIO | G9: 3.365 | H9: 427465.79 | I9: 12114 | J9: 12114 | K9: RITMO LOGISTICA S/A
A10: IPAUSSU | B10: 46124 | C10: 8013465 | D10: IPA-LN-000 | E10: 881 | F10: DESLOCAMENTO CARREGADO | G10: 5.5052778 | H10: 426423.95 | I10: 19819 | J10: 19819 | K10: RITMO LOGISTICA S/A
A11: IPAUSSU | B11: 46124 | C11: 8013482 | D11: IPA-LN-000 | E11: 881 | F11: DESLOCAMENTO CARREGADO | G11: 4.7358333 | H11: 421365.03 | I11: 17049 | J11: 17049 | K11: RITMO LOGISTICA S/A
A12: IPAUSSU | B12: 46124 | C12: 8013472 | D12: IPA-LN-000 | E12: 895 | F12: DESLOCAMENTO VAZIO | G12: 3.0741667 | H12: 415361.29 | I12: 11067 | J12: 11067 | K12: RITMO LOGISTICA S/A
A13: IPAUSSU | B13: 46118 | C13: 8013461 | D13: IPA-LN-000 | E13: 881 | F13: DESLOCAMENTO CARREGADO | G13: 3.965 | H13: 411676.07 | I13: 14242 | J13: 14274 | K13: RITMO LOGISTICA S/A
... A575: IPAUSSU | B575: 46118 | C575: 8013472 | D575: IPA-LN-000 | E575: 254 | F575: MANUTENCAO EXTERNA CONCESSIONARIA | G575: 2.3786111 | H575: 4.59 | I575: 1 | J575: 566 | K575: RITMO LOGISTICA S/A
A576: IPAUSSU | B576: 46116 | C576: 8013460 | D576: IPA-LN-000 | E576: 254 | F576: MANUTENCAO EXTERNA CONCESSIONARIA | G576: 4.5788889 | H576: 0 | J576: 414 | K576: RITMO LOGISTICA S/A
A577: IPAUSSU | B577: 46116 | C577: 8013461 | D577: IPA-LN-000 | E577: 254 | F577: MANUTENCAO EXTERNA CONCESSIONARIA | G577: 9.7933333 | H577: 0 | J577: 0 | K577: RITMO LOGISTICA S/A
A578: IPAUSSU | B578: 46116 | C578: 8013465 | D578: IPA-LN-000 | E578: 254 | F578: MANUTENCAO EXTERNA CONCESSIONARIA | G578: 4.1519444 | H578: 0 | J578: 415 | K578: RITMO LOGISTICA S/A
A579: IPAUSSU | B579: 46116 | C579: 8013465 | D579: IPA-LN-000 | E579: 833 | F579: DESLOCAMENTO | G579: 0.011111111 | H579: 0 | J579: 0 | K579: RITMO LOGISTICA S/A
A580: IPAUSSU | B580: 46116 | C580: 8013468 | D580: IPA-LN-000 | E580: 833 | F580: DESLOCAMENTO | G580: 0.034722222 | H580: 0 | J580: 32 | K580: RITMO LOGISTICA S/A
A581: IPAUSSU | B581: 46116 | C581: 8013470 | D581: IPA-LN-000 | E581: 254 | F581: MANUTENCAO EXTERNA CONCESSIONARIA | G581: 6.6969444 | H581: 0 | J581: 0 | K581: RITMO LOGISTICA S/A
A582: IPAUSSU | B582: 46116 | C582: 8013474 | D582: IPA-LN-000 | E582: 254 | F582: MANUTENCAO EXTERNA CONCESSIONARIA | G582: 0.80694444 | H582: 0 | J582: 0 | K582: RITMO LOGISTICA S/A
A583: IPAUSSU | B583: 46116 | C583: 8013475 | D583: IPA-LN-000 | E583: 254 | F583: MANUTENCAO EXTERNA CONCESSIONARIA | G583: 1.8027778 | H583: 0 | J583: 0 | K583: RITMO LOGISTICA S/A
A584: IPAUSSU | B584: 46116 | C584: 8013482 | D584: IPA-LN-000 | E584: 254 | F584: MANUTENCAO EXTERNA CONCESSIONARIA | G584: 9.2813889 | H584: 0 | J584: 652 | K584: RITMO LOGISTICA S/A
A585: IPAUSSU | B585: 46116 | C585: 8013483 | D585: IPA-LN-000 | E585: 254 | F585: MANUTENCAO EXTERNA CONCESSIONARIA | G585: 2.0166667 | H585: 0 | J585: 0 | K585: RITMO LOGISTICA S/A
A586: IPAUSSU | B586: 46116 | C586: 8013484 | D586: IPA-LN-000 | E586: 1109 | F586: MAN PREVENTIVA - MECANICA | G586: 4.1105556 | H586: 0 | J586: 5 | K586: RITMO LOGISTICA S/A
A587: IPAUSSU | B587: 46116 | C587: 8013486 | D587: IPA-LN-000 | E587: 254 | F587: MANUTENCAO EXTERNA CONCESSIONARIA | G587: 4.2016667 | H587: 0 | J587: 454 | K587: RITMO LOGISTICA S/A
... A1383: IPAUSSU | B1383: 46124 | C1383: 8013486 | D1383: IPA-LN-000 | E1383: 896 | F1383: DESCARREGAMENTO HILO | G1383: 1.51 | H1383: 0 | J1383: 292 | K1383: RITMO LOGISTICA S/A
A1384: IPAUSSU | B1384: 46116 | C1384: 8013460 | D1384: IPA-LN-000 | E1384: 834 | F1384: SEM APONTAMENTO | G1384: 1.9577778 | K1384: RITMO LOGISTICA S/A
A1385: IPAUSSU | B1385: 46116 | C1385: 8013460 | D1385: IPA-LN-000 | E1385: 835 | F1385: TEMPO INDETERMINADO | G1385: 3 | K1385: RITMO LOGISTICA S/A
A1386: IPAUSSU | B1386: 46116 | C1386: 8013465 | D1386: IPA-LN-000 | E1386: 834 | F1386: SEM APONTAMENTO | G1386: 1.4041667 | K1386: RITMO LOGISTICA S/A
A1387: IPAUSSU | B1387: 46116 | C1387: 8013465 | D1387: IPA-LN-000 | E1387: 835 | F1387: TEMPO INDETERMINADO | G1387: 4 | K1387: RITMO LOGISTICA S/A
A1388: IPAUSSU | B1388: 46116 | C1388: 8013468 | D1388: IPA-LN-000 | E1388: 834 | F1388: SEM APONTAMENTO | G1388: 1.7291667 | K1388: RITMO LOGISTICA S/A
A1389: IPAUSSU | B1389: 46116 | C1389: 8013468 | D1389: IPA-LN-000 | E1389: 835 | F1389: TEMPO INDETERMINADO | G1389: 8 | K1389: RITMO LOGISTICA S/A
A1390: IPAUSSU | B1390: 46116 | C1390: 8013470 | D1390: IPA-LN-000 | E1390: 834 | F1390: SEM APONTAMENTO | G1390: 1.3030556 | K1390: RITMO LOGISTICA S/A
A1391: IPAUSSU | B1391: 46116 | C1391: 8013470 | D1391: IPA-LN-000 | E1391: 835 | F1391: TEMPO INDETERMINADO | G1391: 1 | K1391: RITMO LOGISTICA S/A
A1392: IPAUSSU | B1392: 46116 | C1392: 8013473 | D1392: IPA-LN-000 | E1392: 835 | F1392: TEMPO INDETERMINADO | G1392: 2 | K1392: RITMO LOGISTICA S/A
A1393: IPAUSSU | B1393: 46116 | C1393: 8013474 | D1393: IPA-LN-000 | E1393: 834 | F1393: SEM APONTAMENTO | G1393: 1.5027778 | K1393: RITMO LOGISTICA S/A
A1394: IPAUSSU | B1394: 46116 | C1394: 8013475 | D1394: IPA-LN-000 | E1394: 834 | F1394: SEM APONTAMENTO | G1394: 0.19722222 | K1394: RITMO LOGISTICA S/A
A1395: IPAUSSU | B1395: 46116 | C1395: 8013476 | D1395: IPA-LN-000 | E1395: 835 | F1395: TEMPO INDETERMINADO | G1395: 2 | K1395: RITMO LOGISTICA S/A
... A1436: IPAUSSU | B1436: 46124 | C1436: 8013485 | D1436: IPA-LN-000 | E1436: 835 | F1436: TEMPO INDETERMINADO | G1436: 5.325 | K1436: RITMO LOGISTICA S/A

Sheet Apoio_Tempo_Cargas
A1: EQUIPAMENTO | B1: DATA | C1: FRENTE | D1: FAZENDA | E1: PARTIDA_USINA | F1: CHEGADA_LAVOURA | G1: SAIDA_LAVOURA | H1: CHEGADA_PATIO | I1: FIM_CICLO | J1: t1 (min) | K1: t2 (min) | L1: t3 (min) | M1: t4 (min) | N1: Max T2 | O1: Considerar T2 | P1: Max T4 | Q1: Considerar T4 | R1: OPL | S1: QT_LIQUIDO (kg) | T1: QTD_CARGAS | U1: DENSIDADE (ton/viag) | V1: POND_DIST | W1: RAIO (km)
A2: ='Base de tempo'!C2 -> 8013478 | B2: ='Base de tempo'!B2 -> 46121 | C2: ='Base de tempo'!D2 -> 352 | D2: ='Base de tempo'!E2 -> 19817 | E2: ='Base de tempo'!F2 -> 46118.692 | F2: ='Base de tempo'!G2 -> 46121.639 | G2: ='Base de tempo'!H2 -> 46123.45 | H2: ='Base de tempo'!I2 -> 46123.873 | I2: ='Base de tempo'!J2 -> 46123.919 | J2: =IFERROR(IF((F2-E2)>0,(F2-E2)*24*60,""),"") -> 4243.0667 | K2: =IFERROR(IF((G2-F2)>0,(G2-F2)*24*60,""),"") -> 2608.3167 | L2: =IFERROR(IF((H2-G2)>0,(H2-G2)*24*60,""),"") -> 608.48333 | M2: =IFERROR(IF((I2-H2)>0,(I2-H2)*24*60,""),"") -> 65.75 | N2: ='Base de tempo'!O2 -> 90 | O2: ='Base de tempo'!P2 -> 0 | P2: ='Base de tempo'!Q2 -> 105 | Q2: ='Base de tempo'!R2 -> Sim | R2: ='Base de tempo'!S2 -> RITMO | S2: =IFERROR(SUMIFS('Base cargas'!H$2:H$36,'Base cargas'!G$2:G$36,A2),0) -> 131700 | T2: =IFERROR(SUMIFS('Base cargas'!J$2:J$36,'Base cargas'!G$2:G$36,A2),0) -> 4 | U2: =IFERROR(S2/T2/1000,"") -> 32.925 | V2: =IFERROR(SUMIFS('Base cargas'!K$2:K$36,'Base cargas'!G$2:G$36,A2),0) -> 7023480 | W2: =IFERROR(V2/S2,"") -> 53.329385
A3: ='Base de tempo'!C3 -> 8013468 | B3: ='Base de tempo'!B3 -> 46117 | C3: ='Base de tempo'!D3 -> 352 | D3: ='Base de tempo'!E3 -> 19817 | E3: ='Base de tempo'!F3 -> 46117.923 | F3: ='Base de tempo'!G3 -> 46117.983 | G3: ='Base de tempo'!H3 -> 46118.497 | H3: ='Base de tempo'!I3 -> 46118.588 | I3: ='Base de tempo'!J3 -> 46119.78 | J3: =IFERROR(IF((F3-E3)>0,(F3-E3)*24*60,""),"") -> 85.9 | K3: =IFERROR(IF((G3-F3)>0,(G3-F3)*24*60,""),"") -> 739.65 | L3: =IFERROR(IF((H3-G3)>0,(H3-G3)*24*60,""),"") -> 131.73333 | M3: =IFERROR(IF((I3-H3)>0,(I3-H3)*24*60,""),"") -> 1716.45 | N3: ='Base de tempo'!O3 -> 90 | O3: ='Base de tempo'!P3 -> 0 | P3: ='Base de tempo'!Q3 -> 105 | Q3: ='Base de tempo'!R3 -> 0 | R3: ='Base de tempo'!S3 -> RITMO | S3: =IFERROR(SUMIFS('Base cargas'!H$2:H$36,'Base cargas'!G$2:G$36,A3),0) -> 211520 | T3: =IFERROR(SUMIFS('Base cargas'!J$2:J$36,'Base cargas'!G$2:G$36,A3),0) -> 6 | U3: =IFERROR(S3/T3/1000,"") -> 35.253333 | V3: =IFERROR(SUMIFS('Base cargas'!K$2:K$36,'Base cargas'!G$2:G$36,A3),0) -> 10783194 | W3: =IFERROR(V3/S3,"") -> 50.979548
A4: ='Base de tempo'!C4 -> 8013482 | B4: ='Base de tempo'!B4 -> 46117 | C4: ='Base de tempo'!D4 -> 352 | D4: ='Base de tempo'!E4 -> 19817 | E4: ='Base de tempo'!F4 -> 46117.789 | F4: ='Base de tempo'!G4 -> 46117.847 | G4: ='Base de tempo'!H4 -> 46118.3 | H4: ='Base de tempo'!I4 -> 46118.692 | I4: ='Base de tempo'!J4 -> 46123.852 | J4: =IFERROR(IF((F4-E4)>0,(F4-E4)*24*60,""),"") -> 84.416667 | K4: =IFERROR(IF((G4-F4)>0,(G4-F4)*24*60,""),"") -> 652.01667 | L4: =IFERROR(IF((H4-G4)>0,(H4-G4)*24*60,""),"") -> 563.85 | M4: =IFERROR(IF((I4-H4)>0,(I4-H4)*24*60,""),"") -> 7430.6333 | N4: ='Base de tempo'!O4 -> 90 | O4: ='Base de tempo'!P4 -> 0 | P4: ='Base de tempo'!Q4 -> 105 | Q4: ='Base de tempo'!R4 -> 0 | R4: ='Base de tempo'!S4 -> RITMO | S4: =IFERROR(SUMIFS('Base cargas'!H$2:H$36,'Base cargas'!G$2:G$36,A4),0) -> 57540 | T4: =IFERROR(SUMIFS('Base cargas'!J$2:J$36,'Base cargas'!G$2:G$36,A4),0) -> 2 | U4: =IFERROR(S4/T4/1000,"") -> 28.77 | V4: =IFERROR(SUMIFS('Base cargas'!K$2:K$36,'Base cargas'!G$2:G$36,A4),0) -> 3279780 | W4: =IFERROR(V4/S4,"") -> 57
A5: ='Base de tempo'!C5 -> 8013484 | B5: ='Base de tempo'!B5 -> 46117 | C5: ='Base de tempo'!D5 -> 352 | D5: ='Base de tempo'!E5 -> 19817 | E5: ='Base de tempo'!F5 -> 46117.745 | F5: ='Base de tempo'!G5 -> 46117.801 | G5: ='Base de tempo'!H5 -> 46118.192 | H5: ='Base de tempo'!I5 -> 46118.403 | I5: ='Base de tempo'!J5 -> 46119.945 | J5: =IFERROR(IF((F5-E5)>0,(F5-E5)*24*60,""),"") -> 81.15 | K5: =IFERROR(IF((G5-F5)>0,(G5-F5)*24*60,""),"") -> 563.33333 | L5: =IFERROR(IF((H5-G5)>0,(H5-G5)*24*60,""),"") -> 303 | M5: =IFERROR(IF((I5-H5)>0,(I5-H5)*24*60,""),"") -> 2220.5833 | N5: ='Base de tempo'!O5 -> 90 | O5: ='Base de tempo'!P5 -> 0 | P5: ='Base de tempo'!Q5 -> 105 | Q5: ='Base de tempo'!R5 -> 0 | R5: ='Base de tempo'!S5 -> RITMO | S5: =IFERROR(SUMIFS('Base cargas'!H$2:H$36,'Base cargas'!G$2:G$36,A5),0) -> 145760 | T5: =IFERROR(SUMIFS('Base cargas'!J$2:J$36,'Base cargas'!G$2:G$36,A5),0) -> 4 | U5: =IFERROR(S5/T5/1000,"") -> 36.44 | V5: =IFERROR(SUMIFS('Base cargas'!K$2:K$36,'Base cargas'!G$2:G$36,A5),0) -> 7142240 | W5: =IFERROR(V5/S5,"") -> 49
A6: ='Base de tempo'!C6 -> 8013472 | B6: ='Base de tempo'!B6 -> 46117 | C6: ='Base de tempo'!D6 -> 353 | D6: ='Base de tempo'!E6 -> 19461 | E6: ='Base de tempo'!F6 -> 46117.902 | F6: ='Base de tempo'!G6 -> 46117.972 | G6: ='Base de tempo'!H6 -> 46118.232 | H6: ='Base de tempo'!I6 -> 46118.324 | I6: ='Base de tempo'!J6 -> 46118.542 | J6: =IFERROR(IF((F6-E6)>0,(F6-E6)*24*60,""),"") -> 99.75 | K6: =IFERROR(IF((G6-F6)>0,(G6-F6)*24*60,""),"") -> 374.66667 | L6: =IFERROR(IF((H6-G6)>0,(H6-G6)*24*60,""),"") -> 133.48333 | M6: =IFERROR(IF((I6-H6)>0,(I6-H6)*24*60,""),"") -> 313.06667 | N6: ='Base de tempo'!O6 -> 90 | O6: ='Base de tempo'!P6 -> 0 | P6: ='Base de tempo'!Q6 -> 105 | Q6: ='Base de tempo'!R6 -> 0 | R6: ='Base de tempo'!S6 -> RITMO | S6: =IFERROR(SUMIFS('Base cargas'!H$2:H$36,'Base cargas'!G$2:G$36,A6),0) -> 150920 | T6: =IFERROR(SUMIFS('Base cargas'!J$2:J$36,'Base cargas'!G$2:G$36,A6),0) -> 4 | U6: =IFERROR(S6/T6/1000,"") -> 37.73 | V6: =IFERROR(SUMIFS('Base cargas'!K$2:K$36,'Base cargas'!G$2:G$36,A6),0) -> 7469960 | W6: =IFERROR(V6/S6,"") -> 49.496157
A7: ='Base de tempo'!C7 -> 8013473 | B7: ='Base de tempo'!B7 -> 46117 | C7: ='Base de tempo'!D7 -> 352 | D7: ='Base de tempo'!E7 -> 19817 | E7: ='Base de tempo'!F7 -> 46117.732 | F7: ='Base de tempo'!G7 -> 46117.8 | G7: ='Base de tempo'!H7 -> 46118.011 | H7: ='Base de tempo'!I7 -> 46118.201 | I7: ='Base de tempo'!J7 -> 46118.246 | J7: =IFERROR(IF((F7-E7)>0,(F7-E7)*24*60,""),"") -> 98.383333 | K7: =IFERROR(IF((G7-F7)>0,(G7-F7)*24*60,""),"") -> 302.73333 | L7: =IFERROR(IF((H7-G7)>0,(H7-G7)*24*60,""),"") -> 274.03333 | M7: =IFERROR(IF((I7-H7)>0,(I7-H7)*24*60,""),"") -> 64.216667 | N7: ='Base de tempo'!O7 -> 90 | O7: ='Base de tempo'!P7 -> 0 | P7: ='Base de tempo'!Q7 -> 105 | Q7: ='Base de tempo'!R7 -> Sim | R7: ='Base de tempo'!S7 -> RITMO | S7: =IFERROR(SUMIFS('Base cargas'!H$2:H$36,'Base cargas'!G$2:G$36,A7),0) -> 134820 | T7: =IFERROR(SUMIFS('Base cargas'!J$2:J$36,'Base cargas'!G$2:G$36,A7),0) -> 4 | U7: =IFERROR(S7/T7/1000,"") -> 33.705 | V7: =IFERROR(SUMIFS('Base cargas'!K$2:K$36,'Base cargas'!G$2:G$36,A7),0) -> 7098980 | W7: =IFERROR(V7/S7,"") -> 52.655244
A8: ='Base de tempo'!C8 -> 8013462 | B8: ='Base de tempo'!B8 -> 46117 | C8: ='Base de tempo'!D8 -> 351 | D8: ='Base de tempo'!E8 -> 9126 | E8: ='Base de tempo'!F8 -> 46117.673 | F8: ='Base de tempo'!G8 -> 46117.709 | G8: ='Base de tempo'!H8 -> 46117.849 | H8: ='Base de tempo'!I8 -> 46117.863 | I8: ='Base de tempo'!J8 -> 46117.863 | J8: =IFERROR(IF((F8-E8)>0,(F8-E8)*24*60,""),"") -> 52 | K8: =IFERROR(IF((G8-F8)>0,(G8-F8)*24*60,""),"") -> 201.73333 | L8: =IFERROR(IF((H8-G8)>0,(H8-G8)*24*60,""),"") -> 19.8 | M8: =IFERROR(IF((I8-H8)>0,(I8-H8)*24*60,""),"") -> 0.68333334 | N8: ='Base de tempo'!O8 -> 90 | O8: ='Base de tempo'!P8 -> 0 | P8: ='Base de tempo'!Q8 -> 105 | Q8: ='Base de tempo'!R8 -> 0 | R8: ='Base de tempo'!S8 -> RITMO | S8: =IFERROR(SUMIFS('Base cargas'!H$2:H$36,'Base cargas'!G$2:G$36,A8),0) -> 130100 | T8: =IFERROR(SUMIFS('Base cargas'!J$2:J$36,'Base cargas'!G$2:G$36,A8),0) -> 4 | U8: =IFERROR(S8/T8/1000,"") -> 32.525 | V8: =IFERROR(SUMIFS('Base cargas'!K$2:K$36,'Base cargas'!G$2:G$36,A8),0) -> 6939140 | W8: =IFERROR(V8/S8,"") -> 53.336972
A9: ='Base de tempo'!C9 -> 8013475 | B9: ='Base de tempo'!B9 -> 46117 | C9: ='Base de tempo'!D9 -> 351 | D9: ='Base de tempo'!E9 -> 19679 | E9: ='Base de tempo'!F9 -> 46117.8 | F9: ='Base de tempo'!G9 -> 46117.844 | G9: ='Base de tempo'!H9 -> 46117.983 | H9: ='Base de tempo'!I9 -> 46118.014 | I9: ='Base de tempo'!J9 -> 46118.172 | J9: =IFERROR(IF((F9-E9)>0,(F9-E9)*24*60,""),"") -> 63.166667 | K9: =IFERROR(IF((G9-F9)>0,(G9-F9)*24*60,""),"") -> 199.5 | L9: =IFERROR(IF((H9-G9)>0,(H9-G9)*24*60,""),"") -> 44.25 | M9: =IFERROR(IF((I9-H9)>0,(I9-H9)*24*60,""),"") -> 228.23333 | N9: ='Base de tempo'!O9 -> 90 | O9: ='Base de tempo'!P9 -> 0 | P9: ='Base de tempo'!Q9 -> 105 | Q9: ='Base de tempo'!R9 -> 0 | R9: ='Base de tempo'!S9 -> RITMO | S9: =IFERROR(SUMIFS('Base cargas'!H$2:H$36,'Base cargas'!G$2:G$36,A9),0) -> 0 | T9: =IFERROR(SUMIFS('Base cargas'!J$2:J$36,'Base cargas'!G$2:G$36,A9),0) -> 0 | U9: =IFERROR(S9/T9/1000,"") | V9: =IFERROR(SUMIFS('Base cargas'!K$2:K$36,'Base cargas'!G$2:G$36,A9),0) -> 0 | W9: =IFERROR(V9/S9,"")
A10: ='Base de tempo'!C10 -> 8013462 | B10: ='Base de tempo'!B10 -> 46124 | C10: ='Base de tempo'!D10 -> 352 | D10: ='Base de tempo'!E10 -> 19817 | E10: ='Base de tempo'!F10 -> 46124.631 | F10: ='Base de tempo'!G10 -> 46124.679 | G10: ='Base de tempo'!H10 -> 46124.811 | H10: ='Base de tempo'!I10 -> 46124.822 | I10: ='Base de tempo'!J10 -> 46124.958 | J10: =IFERROR(IF((F10-E10)>0,(F10-E10)*24*60,""),"") -> 70.033333 | K10: =IFERROR(IF((G10-F10)>0,(G10-F10)*24*60,""),"") -> 189.65 | L10: =IFERROR(IF((H10-G10)>0,(H10-G10)*24*60,""),"") -> 15.7 | M10: =IFERROR(IF((I10-H10)>0,(I10-H10)*24*60,""),"") -> 195.36667 | N10: ='Base de tempo'!O10 -> 90 | O10: ='Base de tempo'!P10 -> 0 | P10: ='Base de tempo'!Q10 -> 105 | Q10: ='Base de tempo'!R10 -> 0 | R10: ='Base de tempo'!S10 -> RITMO | S10: =IFERROR(SUMIFS('Base cargas'!H$2:H$36,'Base cargas'!G$2:G$36,A10),0) -> 130100 | T10: =IFERROR(SUMIFS('Base cargas'!J$2:J$36,'Base cargas'!G$2:G$36,A10),0) -> 4 | U10: =IFERROR(S10/T10/1000,"") -> 32.525 | V10: =IFERROR(SUMIFS('Base cargas'!K$2:K$36,'Base cargas'!G$2:G$36,A10),0) -> 6939140 | W10: =IFERROR(V10/S10,"") -> 53.336972
A11: ='Base de tempo'!C11 -> 8013470 | B11: ='Base de tempo'!B11 -> 46119 | C11: ='Base de tempo'!D11 -> 353 | D11: ='Base de tempo'!E11 -> 19461 | E11: ='Base de tempo'!F11 -> 46119.793 | F11: ='Base de tempo'!G11 -> 46119.85 | G11: ='Base de tempo'!H11 -> 46119.971 | H11: ='Base de tempo'!I11 -> 46120.042 | I11: ='Base de tempo'!J11 -> 46123.694 | J11: =IFERROR(IF((F11-E11)>0,(F11-E11)*24*60,""),"") -> 82.566667 | K11: =IFERROR(IF((G11-F11)>0,(G11-F11)*24*60,""),"") -> 174.21667 | L11: =IFERROR(IF((H11-G11)>0,(H11-G11)*24*60,""),"") -> 101.76667 | M11: =IFERROR(IF((I11-H11)>0,(I11-H11)*24*60,""),"") -> 5258.6667 | N11: ='Base de tempo'!O11 -> 90 | O11: ='Base de tempo'!P11 -> 0 | P11: ='Base de tempo'!Q11 -> 105 | Q11: ='Base de tempo'!R11 -> 0 | R11: ='Base de tempo'!S11 -> RITMO | S11: =IFERROR(SUMIFS('Base cargas'!H$2:H$36,'Base cargas'!G$2:G$36,A11),0) -> 217060 | T11: =IFERROR(SUMIFS('Base cargas'!J$2:J$36,'Base cargas'!G$2:G$36,A11),0) -> 6 | U11: =IFERROR(S11/T11/1000,"") -> 36.176667 | V11: =IFERROR(SUMIFS('Base cargas'!K$2:K$36,'Base cargas'!G$2:G$36,A11),0) -> 10657336 | W11: =IFERROR(V11/S11,"") -> 49.098572
A12: ='Base de tempo'!C12 -> 8013468 | B12: ='Base de tempo'!B12 -> 46123 | C12: ='Base de tempo'!D12 -> 351 | D12: ='Base de tempo'!E12 -> 9143 | E12: ='Base de tempo'!F12 -> 46123.891 | F12: ='Base de tempo'!G12 -> 46123.908 | G12: ='Base de tempo'!H12 -> 46124.015 | H12: ='Base de tempo'!I12 -> 46124.037 | I12: ='Base de tempo'!J12 -> 46124.381 | J12: =IFERROR(IF((F12-E12)>0,(F12-E12)*24*60,""),"") -> 23.516667 | K12: =IFERROR(IF((G12-F12)>0,(G12-F12)*24*60,""),"") -> 154.65 | L12: =IFERROR(IF((H12-G12)>0,(H12-G12)*24*60,""),"") -> 31.183333 | M12: =IFERROR(IF((I12-H12)>0,(I12-H12)*24*60,""),"") -> 495.71667 | N12: ='Base de tempo'!O12 -> 90 | O12: ='Base de tempo'!P12 -> 0 | P12: ='Base de tempo'!Q12 -> 105 | Q12: ='Base de tempo'!R12 -> 0 | R12: ='Base de tempo'!S12 -> RITMO | S12: =IFERROR(SUMIFS('Base cargas'!H$2:H$36,'Base cargas'!G$2:G$36,A12),0) -> 211520 | T12: =IFERROR(SUMIFS('Base cargas'!J$2:J$36,'Base cargas'!G$2:G$36,A12),0) -> 6 | U12: =IFERROR(S12/T12/1000,"") -> 35.253333 | V12: =IFERROR(SUMIFS('Base cargas'!K$2:K$36,'Base cargas'!G$2:G$36,A12),0) -> 10783194 | W12: =IFERROR(V12/S12,"") -> 50.979548
A13: ='Base de tempo'!C13 -> 8013473 | B13: ='Base de tempo'!B13 -> 46123 | C13: ='Base de tempo'!D13 -> 351 | D13: ='Base de tempo'!E13 -> 9143 | E13: ='Base de tempo'!F13 -> 46123.816 | F13: ='Base de tempo'!G13 -> 46123.833 | G13: ='Base de tempo'!H13 -> 46123.94 | H13: ='Base de tempo'!I13 -> 46123.973 | I13: ='Base de tempo'!J13 -> 46124.331 | J13: =IFERROR(IF((F13-E13)>0,(F13-E13)*24*60,""),"") -> 25.05 | K13: =IFERROR(IF((G13-F13)>0,(G13-F13)*24*60,""),"") -> 153.88333 | L13: =IFERROR(IF((H13-G13)>0,(H13-G13)*24*60,""),"") -> 47.833333 | M13: =IFERROR(IF((I13-H13)>0,(I13-H13)*24*60,""),"") -> 515.48333 | N13: ='Base de tempo'!O13 -> 90 | O13: ='Base de tempo'!P13 -> 0 | P13: ='Base de tempo'!Q13 -> 105 | Q13: ='Base de tempo'!R13 -> 0 | R13: ='Base de tempo'!S13 -> RITMO | S13: =IFERROR(SUMIFS('Base cargas'!H$2:H$36,'Base cargas'!G$2:G$36,A13),0) -> 134820 | T13: =IFERROR(SUMIFS('Base cargas'!J$2:J$36,'Base cargas'!G$2:G$36,A13),0) -> 4 | U13: =IFERROR(S13/T13/1000,"") -> 33.705 | V13: =IFERROR(SUMIFS('Base cargas'!K$2:K$36,'Base cargas'!G$2:G$36,A13),0) -> 7098980 | W13: =IFERROR(V13/S13,"") -> 52.655244
... A49: ='Base de tempo'!C49 -> 8013460 | B49: ='Base de tempo'!B49 -> 46123 | C49: ='Base de tempo'!D49 -> 352 | D49: ='Base de tempo'!E49 -> 19817 | E49: ='Base de tempo'!F49 -> 46123.57 | F49: ='Base de tempo'!G49 -> 46123.641 | G49: ='Base de tempo'!H49 -> 46123.666 | H49: ='Base de tempo'!I49 -> 46123.902 | I49: ='Base de tempo'!J49 -> 46124.364 | J49: =IFERROR(IF((F49-E49)>0,(F49-E49)*24*60,""),"") -> 101.41667 | K49: =IFERROR(IF((G49-F49)>0,(G49-F49)*24*60,""),"") -> 35.85 | L49: =IFERROR(IF((H49-G49)>0,(H49-G49)*24*60,""),"") -> 340.08333 | M49: =IFERROR(IF((I49-H49)>0,(I49-H49)*24*60,""),"") -> 665.33333 | N49: ='Base de tempo'!O49 -> 90 | O49: ='Base de tempo'!P49 -> Sim | P49: ='Base de tempo'!Q49 -> 105 | Q49: ='Base de tempo'!R49 -> 0 | R49: ='Base de tempo'!S49 -> RITMO | S49: =IFERROR(SUMIFS('Base cargas'!H$2:H$36,'Base cargas'!G$2:G$36,A49),0) -> 0 | T49: =IFERROR(SUMIFS('Base cargas'!J$2:J$36,'Base cargas'!G$2:G$36,A49),0) -> 0 | U49: =IFERROR(S49/T49/1000,"") | V49: =IFERROR(SUMIFS('Base cargas'!K$2:K$36,'Base cargas'!G$2:G$36,A49),0) -> 0 | W49: =IFERROR(V49/S49,"")

Sheet Apoio_Bordo
A1: EQUIPAMENTO | B1: DATA | C1: TRANSPORTADORA | D1: DESLOC. VAZIO (h) | E1: DESLOC. CARREGADO (h) | F1: DESLOC. OUTROS (h) | G1: CARREGAMENTO (h) | H1: AGUARD. TRANSBORDO (h) | I1: PÁTIO INT+EXT+RES (h) | J1: BALANÇA (h) | K1: MANUT PREV+CORR (h) | L1: MANUT OUTROS (h) | M1: AG. MANUTENCAO (h) | N1: SEM APONTAMENTO (h) | O1: OUTROS (h) | P1: TOTAL HORAS (h) | Q1: VEL_POND VAZIO | R1: HR_OP VAZIO | S1: VEL MÉDIA VAZIO (km/h) | T1: VEL_POND CARREG | U1: HR_OP CARREG | V1: VEL MÉDIA CARREG (km/h) | W1: % DESLOC VAZIO | X1: % DESLOC CARREG | Y1: % OFENSORES
A2: 8013470 | B2: 46124 | C2: RITMO LOGISTICA S/A | D2: =IFERROR(SUMIFS('Base bordo'!G$2:G$746,'Base bordo'!C$2:C$746,A2,'Base bordo'!B$2:B$746,B2,'Base bordo'!F$2:F$746,"DESLOCAMENTO VAZIO"),0) -> 2.2769444 | E2: =IFERROR(SUMIFS('Base bordo'!G$2:G$746,'Base bordo'!C$2:C$746,A2,'Base bordo'!B$2:B$746,B2,'Base bordo'!F$2:F$746,"DESLOCAMENTO CARREGADO"),0) -> 6.3111111 | F2: =IFERROR(SUMIFS('Base bordo'!G$2:G$746,'Base bordo'!C$2:C$746,A2,'Base bordo'!B$2:B$746,B2,'Base bordo'!F$2:F$746,"DESLOCAMENTO"),0) -> 0 | G2: =IFERROR(SUMIFS('Base bordo'!G$2:G$746,'Base bordo'!C$2:C$746,A2,'Base bordo'!B$2:B$746,B2,'Base bordo'!F$2:F$746,"CARREGAMENTO"),0) -> 0 | H2: =IFERROR(SUMIFS('Base bordo'!G$2:G$746,'Base bordo'!C$2:C$746,A2,'Base bordo'!B$2:B$746,B2,'Base bordo'!F$2:F$746,"AGUARDANDO TRANSBORDO"),0) -> 0.24416667 | I2: =IFERROR(SUMIFS('Base bordo'!G$2:G$746,'Base bordo'!C$2:C$746,A2,'Base bordo'!B$2:B$746,B2,'Base bordo'!F$2:F$746,"PÁTIO INTERNO"),0)+IFERROR(SUMIFS('Base bordo'!G$2:G$746,'Base bordo'!C$2:C$746,A2,'Base bordo'!B$2:B$746,B2,'Base bordo'!F$2:F$746,"PÁTIO EXTERNO"),0)+IFERROR(SUMIFS('Base bordo'!G$2:G$746,'Base bordo'!C$2:C$746,A2,'Base bordo'!B$2:B$746,B2,'Base bordo'!F$2:F$746,"PATIO - RESERVA"),0)+IFERROR(SUMIFS('Base bordo'!G$2:G$746,'Base bordo'!C$2:C$746,A2,'Base bordo'!B$2:B$746,B2,'Base bordo'!F$2:F$746,"MANOBRA CARRETAS-PATIO"),0) -> 3.2016667 | J2: =IFERROR(SUMIFS('Base bordo'!G$2:G$746,'Base bordo'!C$2:C$746,A2,'Base bordo'!B$2:B$746,B2,'Base bordo'!F$2:F$746,"BALANÇA - ENTRADA"),0)+IFERROR(SUMIFS('Base bordo'!G$2:G$746,'Base bordo'!C$2:C$746,A2,'Base bordo'!B$2:B$746,B2,'Base bordo'!F$2:F$746,"BALANÇA - SAÍDA"),0) -> 0.21722222 | K2: =IFERROR(SUMIFS('Base bordo'!G$2:G$746,'Base bordo'!C$2:C$746,A2,'Base bordo'!B$2:B$746,B2,'Base bordo'!F$2:F$746,"MAN PREVENTIVA - MECANICA"),0)+IFERROR(SUMIFS('Base bordo'!G$2:G$746,'Base bordo'!C$2:C$746,A2,'Base bordo'!B$2:B$746,B2,'Base bordo'!F$2:F$746,"MAN CORRETIVA - MECANICA"),0) -> 0 | L2: =IFERROR(SUMIFS('Base bordo'!G$2:G$746,'Base bordo'!C$2:C$746,A2,'Base bordo'!B$2:B$746,B2,'Base bordo'!F$2:F$746,"MANUTENCAO - T O"),0)+IFERROR(SUMIFS('Base bordo'!G$2:G$746,'Base bordo'!C$2:C$746,A2,'Base bordo'!B$2:B$746,B2,'Base bordo'!F$2:F$746,"MANUTENCAO BORRACHARIA"),0)+IFERROR(SUMIFS('Base bordo'!G$2:G$746,'Base bordo'!C$2:C$746,A2,'Base bordo'!B$2:B$746,B2,'Base bordo'!F$2:F$746,"MANUTENCAO EXTERNA CONCESSIONARIA"),0)+IFERROR(SUMIFS('Base bordo'!G$2:G$746,'Base bordo'!C$2:C$746,A2,'Base bordo'!B$2:B$746,B2,'Base bordo'!F$2:F$746,"MANUTENCAO TELEMETRIA"),0) -> 0 | M2: =IFERROR(SUMIFS('Base bordo'!G$2:G$746,'Base bordo'!C$2:C$746,A2,'Base bordo'!B$2:B$746,B2,'Base bordo'!F$2:F$746,"AGUARDANDO MANUTENCAO"),0) -> 0 | N2: =IFERROR(SUMIFS('Base bordo'!G$2:G$746,'Base bordo'!C$2:C$746,A2,'Base bordo'!B$2:B$746,B2,'Base bordo'!F$2:F$746,"SEM APONTAMENTO"),0) -> 0 | O2: =IFERROR(P2-SUM(D2:N2),0) -> 0.063333333 | P2: =IFERROR(SUMIFS('Base bordo'!G$2:G$746,'Base bordo'!C$2:C$746,A2,'Base bordo'!B$2:B$746,B2),0) -> 12.314444 | Q2: =IFERROR(SUMIFS('Base bordo'!H$2:H$746,'Base bordo'!C$2:C$746,A2,'Base bordo'!B$2:B$746,B2,'Base bordo'!F$2:F$746,"DESLOCAMENTO VAZIO"),0) -> 282969.98 | R2: =IFERROR(SUMIFS('Base bordo'!I$2:I$746,'Base bordo'!C$2:C$746,A2,'Base bordo'!B$2:B$746,B2,'Base bordo'!F$2:F$746,"DESLOCAMENTO VAZIO"),0) -> 8186 | S2: =IFERROR(Q2/R2,"") -> 34.567552 | T2: =IFERROR(SUMIFS('Base bordo'!H$2:H$746,'Base bordo'!C$2:C$746,A2,'Base bordo'!B$2:B$746,B2,'Base bordo'!F$2:F$746,"DESLOCAMENTO CARREGADO"),0) -> 649243.22 | U2: =IFERROR(SUMIFS('Base bordo'!I$2:I$746,'Base bordo'!C$2:C$746,A2,'Base bordo'!B$2:B$746,B2,'Base bordo'!F$2:F$746,"DESLOCAMENTO CARREGADO"),0) -> 22720 | V2: =IFERROR(T2/U2,"") -> 28.575846 | W2: =IFERROR(D2/P2,0) -> 0.1849003 | X2: =IFERROR(E2/P2,0) -> 0.51249662 | Y2: =IFERROR(1-((D2+E2)/P2),0) -> 0.30260309
A3: 8013461 | B3: 46117 | C3: RITMO LOGISTICA S/A | D3: =IFERROR(SUMIFS('Base bordo'!G$2:G$746,'Base bordo'!C$2:C$746,A3,'Base bordo'!B$2:B$746,B3,'Base bordo'!F$2:F$746,"DESLOCAMENTO VAZIO"),0) -> 4.0352778 | E3: =IFERROR(SUMIFS('Base bordo'!G$2:G$746,'Base bordo'!C$2:C$746,A3,'Base bordo'!B$2:B$746,B3,'Base bordo'!F$2:F$746,"DESLOCAMENTO CARREGADO"),0) -> 0.74527778 | F3: =IFERROR(SUMIFS('Base bordo'!G$2:G$746,'Base bordo'!C$2:C$746,A3,'Base bordo'!B$2:B$746,B3,'Base bordo'!F$2:F$746,"DESLOCAMENTO"),0) -> 0.71555556 | G3: =IFERROR(SUMIFS('Base bordo'!G$2:G$746,'Base bordo'!C$2:C$746,A3,'Base bordo'!B$2:B$746,B3,'Base bordo'!F$2:F$746,"CARREGAMENTO"),0) -> 0.18611111 | H3: =IFERROR(SUMIFS('Base bordo'!G$2:G$746,'Base bordo'!C$2:C$746,A3,'Base bordo'!B$2:B$746,B3,'Base bordo'!F$2:F$746,"AGUARDANDO TRANSBORDO"),0) -> 0.22416667 | I3: =IFERROR(SUMIFS('Base bordo'!G$2:G$746,'Base bordo'!C$2:C$746,A3,'Base bordo'!B$2:B$746,B3,'Base bordo'!F$2:F$746,"PÁTIO INTERNO"),0)+IFERROR(SUMIFS('Base bordo'!G$2:G$746,'Base bordo'!C$2:C$746,A3,'Base bordo'!B$2:B$746,B3,'Base bordo'!F$2:F$746,"PÁTIO EXTERNO"),0)+IFERROR(SUMIFS('Base bordo'!G$2:G$746,'Base bordo'!C$2:C$746,A3,'Base bordo'!B$2:B$746,B3,'Base bordo'!F$2:F$746,"PATIO - RESERVA"),0)+IFERROR(SUMIFS('Base bordo'!G$2:G$746,'Base bordo'!C$2:C$746,A3,'Base bordo'!B$2:B$746,B3,'Base bordo'!F$2:F$746,"MANOBRA CARRETAS-PATIO"),0) -> 0 | J3: =IFERROR(SUMIFS('Base bordo'!G$2:G$746,'Base bordo'!C$2:C$746,A3,'Base bordo'!B$2:B$746,B3,'Base bordo'!F$2:F$746,"BALANÇA - ENTRADA"),0)+IFERROR(SUMIFS('Base bordo'!G$2:G$746,'Base bordo'!C$2:C$746,A3,'Base bordo'!B$2:B$746,B3,'Base bordo'!F$2:F$746,"BALANÇA - SAÍDA"),0) -> 0 | K3: =IFERROR(SUMIFS('Base bordo'!G$2:G$746,'Base bordo'!C$2:C$746,A3,'Base bordo'!B$2:B$746,B3,'Base bordo'!F$2:F$746,"MAN PREVENTIVA - MECANICA"),0)+IFERROR(SUMIFS('Base bordo'!G$2:G$746,'Base bordo'!C$2:C$746,A3,'Base bordo'!B$2:B$746,B3,'Base bordo'!F$2:F$746,"MAN CORRETIVA - MECANICA"),0) -> 0 | L3: =IFERROR(SUMIFS('Base bordo'!G$2:G$746,'Base bordo'!C$2:C$746,A3,'Base bordo'!B$2:B$746,B3,'Base bordo'!F$2:F$746,"MANUTENCAO - T O"),0)+IFERROR(SUMIFS('Base bordo'!G$2:G$746,'Base bordo'!C$2:C$746,A3,'Base bordo'!B$2:B$746,B3,'Base bordo'!F$2:F$746,"MANUTENCAO BORRACHARIA"),0)+IFERROR(SUMIFS('Base bordo'!G$2:G$746,'Base bordo'!C$2:C$746,A3,'Base bordo'!B$2:B$746,B3,'Base bordo'!F$2:F$746,"MANUTENCAO EXTERNA CONCESSIONARIA"),0)+IFERROR(SUMIFS('Base bordo'!G$2:G$746,'Base bordo'!C$2:C$746,A3,'Base bordo'!B$2:B$746,B3,'Base bordo'!F$2:F$746,"MANUTENCAO TELEMETRIA"),0) -> 8.9302778 | M3: =IFERROR(SUMIFS('Base bordo'!G$2:G$746,'Base bordo'!C$2:C$746,A3,'Base bordo'!B$2:B$746,B3,'Base bordo'!F$2:F$746,"AGUARDANDO MANUTENCAO"),0) -> 0 | N3: =IFERROR(SUMIFS('Base bordo'!G$2:G$746,'Base bordo'!C$2:C$746,A3,'Base bordo'!B$2:B$746,B3,'Base bordo'!F$2:F$746,"SEM APONTAMENTO"),0) -> 0.91388889 | O3: =IFERROR(P3-SUM(D3:N3),0) -> 8.2494444 | P3: =IFERROR(SUMIFS('Base bordo'!G$2:G$746,'Base bordo'!C$2:C$746,A3,'Base bordo'!B$2:B$746,B3),0) -> 24 | Q3: =IFERROR(SUMIFS('Base bordo'!H$2:H$746,'Base bordo'!C$2:C$746,A3,'Base bordo'!B$2:B$746,B3,'Base bordo'!F$2:F$746,"DESLOCAMENTO VAZIO"),0) -> 619414.36 | R3: =IFERROR(SUMIFS('Base bordo'!I$2:I$746,'Base bordo'!C$2:C$746,A3,'Base bordo'!B$2:B$746,B3,'Base bordo'!F$2:F$746,"DESLOCAMENTO VAZIO"),0) -> 14527 | S3: =IFERROR(Q3/R3,"") -> 42.638835 | T3: =IFERROR(SUMIFS('Base bordo'!H$2:H$746,'Base bordo'!C$2:C$746,A3,'Base bordo'!B$2:B$746,B3,'Base bordo'!F$2:F$746,"DESLOCAMENTO CARREGADO"),0) -> 37451.12 | U3: =IFERROR(SUMIFS('Base bordo'!I$2:I$746,'Base bordo'!C$2:C$746,A3,'Base bordo'!B$2:B$746,B3,'Base bordo'!F$2:F$746,"DESLOCAMENTO CARREGADO"),0) -> 2683 | V3: =IFERROR(T3/U3,"") -> 13.958673 | W3: =IFERROR(D3/P3,0) -> 0.16813657 | X3: =IFERROR(E3/P3,0) -> 0.031053241 | Y3: =IFERROR(1-((D3+E3)/P3),0) -> 0.80081019
A4: 8013460 | B4: 46117 | C4: RITMO LOGISTICA S/A | D4: =IFERROR(SUMIFS('Base bordo'!G$2:G$746,'Base bordo'!C$2:C$746,A4,'Base bordo'!B$2:B$746,B4,'Base bordo'!F$2:F$746,"DESLOCAMENTO VAZIO"),0) -> 5.2069444 | E4: =IFERROR(SUMIFS('Base bordo'!G$2:G$746,'Base bordo'!C$2:C$746,A4,'Base bordo'!B$2:B$746,B4,'Base bordo'!F$2:F$746,"DESLOCAMENTO CARREGADO"),0) -> 0.55944444 | F4: =IFERROR(SUMIFS('Base bordo'!G$2:G$746,'Base bordo'!C$2:C$746,A4,'Base bordo'!B$2:B$746,B4,'Base bordo'!F$2:F$746,"DESLOCAMENTO"),0) -> 3.0825 | G4: =IFERROR(SUMIFS('Base bordo'!G$2:G$746,'Base bordo'!C$2:C$746,A4,'Base bordo'!B$2:B$746,B4,'Base bordo'!F$2:F$746,"CARREGAMENTO"),0) -> 0.0025 | H4: =IFERROR(SUMIFS('Base bordo'!G$2:G$746,'Base bordo'!C$2:C$746,A4,'Base bordo'!B$2:B$746,B4,'Base bordo'!F$2:F$746,"AGUARDANDO TRANSBORDO"),0) -> 1.0013889 | I4: =IFERROR(SUMIFS('Base bordo'!G$2:G$746,'Base bordo'!C$2:C$746,A4,'Base bordo'!B$2:B$746,B4,'Base bordo'!F$2:F$746,"PÁTIO INTERNO"),0)+IFERROR(SUMIFS('Base bordo'!G$2:G$746,'Base bordo'!C$2:C$746,A4,'Base bordo'!B$2:B$746,B4,'Base bordo'!F$2:F$746,"PÁTIO EXTERNO"),0)+IFERROR(SUMIFS('Base bordo'!G$2:G$746,'Base bordo'!C$2:C$746,A4,'Base bordo'!B$2:B$746,B4,'Base bordo'!F$2:F$746,"PATIO - RESERVA"),0)+IFERROR(SUMIFS('Base bordo'!G$2:G$746,'Base bordo'!C$2:C$746,A4,'Base bordo'!B$2:B$746,B4,'Base bordo'!F$2:F$746,"MANOBRA CARRETAS-PATIO"),0) -> 0.54972222 | J4: =IFERROR(SUMIFS('Base bordo'!G$2:G$746,'Base bordo'!C$2:C$746,A4,'Base bordo'!B$2:B$746,B4,'Base bordo'!F$2:F$746,"BALANÇA - ENTRADA"),0)+IFERROR(SUMIFS('Base bordo'!G$2:G$746,'Base bordo'!C$2:C$746,A4,'Base bordo'!B$2:B$746,B4,'Base bordo'!F$2:F$746,"BALANÇA - SAÍDA"),0) -> 0 | K4: =IFERROR(SUMIFS('Base bordo'!G$2:G$746,'Base bordo'!C$2:C$746,A4,'Base bordo'!B$2:B$746,B4,'Base bordo'!F$2:F$746,"MAN PREVENTIVA - MECANICA"),0)+IFERROR(SUMIFS('Base bordo'!G$2:G$746,'Base bordo'!C$2:C$746,A4,'Base bordo'!B$2:B$746,B4,'Base bordo'!F$2:F$746,"MAN CORRETIVA - MECANICA"),0) -> 0 | L4: =IFERROR(SUMIFS('Base bordo'!G$2:G$746,'Base bordo'!C$2:C$746,A4,'Base bordo'!B$2:B$746,B4,'Base bordo'!F$2:F$746,"MANUTENCAO - T O"),0)+IFERROR(SUMIFS('Base bordo'!G$2:G$746,'Base bordo'!C$2:C$746,A4,'Base bordo'!B$2:B$746,B4,'Base bordo'!F$2:F$746,"MANUTENCAO BORRACHARIA"),0)+IFERROR(SUMIFS('Base bordo'!G$2:G$746,'Base bordo'!C$2:C$746,A4,'Base bordo'!B$2:B$746,B4,'Base bordo'!F$2:F$746,"MANUTENCAO EXTERNA CONCESSIONARIA"),0)+IFERROR(SUMIFS('Base bordo'!G$2:G$746,'Base bordo'!C$2:C$746,A4,'Base bordo'!B$2:B$746,B4,'Base bordo'!F$2:F$746,"MANUTENCAO TELEMETRIA"),0) -> 10.766111 | M4: =IFERROR(SUMIFS('Base bordo'!G$2:G$746,'Base bordo'!C$2:C$746,A4,'Base bordo'!B$2:B$746,B4,'Base bordo'!F$2:F$746,"AGUARDANDO MANUTENCAO"),0) -> 0 | N4: =IFERROR(SUMIFS('Base bordo'!G$2:G$746,'Base bordo'!C$2:C$746,A4,'Base bordo'!B$2:B$746,B4,'Base bordo'!F$2:F$746,"SEM APONTAMENTO"),0) -> 0.29444444 | O4: =IFERROR(P4-SUM(D4:N4),0) -> 2.5369444 | P4: =IFERROR(SUMIFS('Base bordo'!G$2:G$746,'Base bordo'!C$2:C$746,A4,'Base bordo'!B$2:B$746,B4),0) -> 24 | Q4: =IFERROR(SUMIFS('Base bordo'!H$2:H$746,'Base bordo'!C$2:C$746,A4,'Base bordo'!B$2:B$746,B4,'Base bordo'!F$2:F$746,"DESLOCAMENTO VAZIO"),0) -> 595925.09 | R4: =IFERROR(SUMIFS('Base bordo'!I$2:I$746,'Base bordo'!C$2:C$746,A4,'Base bordo'!B$2:B$746,B4,'Base bordo'!F$2:F$746,"DESLOCAMENTO VAZIO"),0) -> 18745 | S4: =IFERROR(Q4/R4,"") -> 31.791149 | T4: =IFERROR(SUMIFS('Base bordo'!H$2:H$746,'Base bordo'!C$2:C$746,A4,'Base bordo'!B$2:B$746,B4,'Base bordo'!F$2:F$746,"DESLOCAMENTO CARREGADO"),0) -> 52858.36 | U4: =IFERROR(SUMIFS('Base bordo'!I$2:I$746,'Base bordo'!C$2:C$746,A4,'Base bordo'!B$2:B$746,B4,'Base bordo'!F$2:F$746,"DESLOCAMENTO CARREGADO"),0) -> 2014 | V4: =IFERROR(T4/U4,"") -> 26.245462 | W4: =IFERROR(D4/P4,0) -> 0.21695602 | X4: =IFERROR(E4/P4,0) -> 0.023310185 | Y4: =IFERROR(1-((D4+E4)/P4),0) -> 0.7597338
A5: 8013470 | B5: 46117 | C5: RITMO LOGISTICA S/A | D5: =IFERROR(SUMIFS('Base bordo'!G$2:G$746,'Base bordo'!C$2:C$746,A5,'Base bordo'!B$2:B$746,B5,'Base bordo'!F$2:F$746,"DESLOCAMENTO VAZIO"),0) -> 5.2283333 | E5: =IFERROR(SUMIFS('Base bordo'!G$2:G$746,'Base bordo'!C$2:C$746,A5,'Base bordo'!B$2:B$746,B5,'Base bordo'!F$2:F$746,"DESLOCAMENTO CARREGADO"),0) -> 1.9622222 | F5: =IFERROR(SUMIFS('Base bordo'!G$2:G$746,'Base bordo'!C$2:C$746,A5,'Base bordo'!B$2:B$746,B5,'Base bordo'!F$2:F$746,"DESLOCAMENTO"),0) -> 0 | G5: =IFERROR(SUMIFS('Base bordo'!G$2:G$746,'Base bordo'!C$2:C$746,A5,'Base bordo'!B$2:B$746,B5,'Base bordo'!F$2:F$746,"CARREGAMENTO"),0) -> 1.6741667 | H5: =IFERROR(SUMIFS('Base bordo'!G$2:G$746,'Base bordo'!C$2:C$746,A5,'Base bordo'!B$2:B$746,B5,'Base bordo'!F$2:F$746,"AGUARDANDO TRANSBORDO"),0) -> 0.22305556 | I5: =IFERROR(SUMIFS('Base bordo'!G$2:G$746,'Base bordo'!C$2:C$746,A5,'Base bordo'!B$2:B$746,B5,'Base bordo'!F$2:F$746,"PÁTIO INTERNO"),0)+IFERROR(SUMIFS('Base bordo'!G$2:G$746,'Base bordo'!C$2:C$746,A5,'Base bordo'!B$2:B$746,B5,'Base bordo'!F$2:F$746,"PÁTIO EXTERNO"),0)+IFERROR(SUMIFS('Base bordo'!G$2:G$746,'Base bordo'!C$2:C$746,A5,'Base bordo'!B$2:B$746,B5,'Base bordo'!F$2:F$746,"PATIO - RESERVA"),0)+IFERROR(SUMIFS('Base bordo'!G$2:G$746,'Base bordo'!C$2:C$746,A5,'Base bordo'!B$2:B$746,B5,'Base bordo'!F$2:F$746,"MANOBRA CARRETAS-PATIO"),0) -> 0.64583333 | J5: =IFERROR(SUMIFS('Base bordo'!G$2:G$746,'Base bordo'!C$2:C$746,A5,'Base bordo'!B$2:B$746,B5,'Base bordo'!F$2:F$746,"BALANÇA - ENTRADA"),0)+IFERROR(SUMIFS('Base bordo'!G$2:G$746,'Base bordo'!C$2:C$746,A5,'Base bordo'!B$2:B$746,B5,'Base bordo'!F$2:F$746,"BALANÇA - SAÍDA"),0) -> 0 | K5: =IFERROR(SUMIFS('Base bordo'!G$2:G$746,'Base bordo'!C$2:C$746,A5,'Base bordo'!B$2:B$746,B5,'Base bordo'!F$2:F$746,"MAN PREVENTIVA - MECANICA"),0)+IFERROR(SUMIFS('Base bordo'!G$2:G$746,'Base bordo'!C$2:C$746,A5,'Base bordo'!B$2:B$746,B5,'Base bordo'!F$2:F$746,"MAN CORRETIVA - MECANICA"),0) -> 0 | L5: =IFERROR(SUMIFS('Base bordo'!G$2:G$746,'Base bordo'!C$2:C$746,A5,'Base bordo'!B$2:B$746,B5,'Base bordo'!F$2:F$746,"MANUTENCAO - T O"),0)+IFERROR(SUMIFS('Base bordo'!G$2:G$746,'Base bordo'!C$2:C$746,A5,'Base bordo'!B$2:B$746,B5,'Base bordo'!F$2:F$746,"MANUTENCAO BORRACHARIA"),0)+IFERROR(SUMIFS('Base bordo'!G$2:G$746,'Base bordo'!C$2:C$746,A5,'Base bordo'!B$2:B$746,B5,'Base bordo'!F$2:F$746,"MANUTENCAO EXTERNA CONCESSIONARIA"),0)+IFERROR(SUMIFS('Base bordo'!G$2:G$746,'Base bordo'!C$2:C$746,A5,'Base bordo'!B$2:B$746,B5,'Base bordo'!F$2:F$746,"MANUTENCAO TELEMETRIA"),0) -> 11.065556 | M5: =IFERROR(SUMIFS('Base bordo'!G$2:G$746,'Base bordo'!C$2:C$746,A5,'Base bordo'!B$2:B$746,B5,'Base bordo'!F$2:F$746,"AGUARDANDO MANUTENCAO"),0) -> 0.04 | N5: =IFERROR(SUMIFS('Base bordo'!G$2:G$746,'Base bordo'!C$2:C$746,A5,'Base bordo'!B$2:B$746,B5,'Base bordo'!F$2:F$746,"SEM APONTAMENTO"),0) -> 0 | O5: =IFERROR(P5-SUM(D5:N5),0) -> 3.1608333 | P5: =IFERROR(SUMIFS('Base bordo'!G$2:G$746,'Base bordo'!C$2:C$746,A5,'Base bordo'!B$2:B$746,B5),0) -> 24 | Q5: =IFERROR(SUMIFS('Base bordo'!H$2:H$746,'Base bordo'!C$2:C$746,A5,'Base bordo'!B$2:B$746,B5,'Base bordo'!F$2:F$746,"DESLOCAMENTO VAZIO"),0) -> 586699.79 | R5: =IFERROR(SUMIFS('Base bordo'!I$2:I$746,'Base bordo'!C$2:C$746,A5,'Base bordo'!B$2:B$746,B5,'Base bordo'!F$2:F$746,"DESLOCAMENTO VAZIO"),0) -> 18822 | S5: =IFERROR(Q5/R5,"") -> 31.170959 | T5: =IFERROR(SUMIFS('Base bordo'!H$2:H$746,'Base bordo'!C$2:C$746,A5,'Base bordo'!B$2:B$746,B5,'Base bordo'!F$2:F$746,"DESLOCAMENTO CARREGADO"),0) -> 166963.32 | U5: =IFERROR(SUMIFS('Base bordo'!I$2:I$746,'Base bordo'!C$2:C$746,A5,'Base bordo'!B$2:B$746,B5,'Base bordo'!F$2:F$746,"DESLOCAMENTO CARREGADO"),0) -> 7064 | V5: =IFERROR(T5/U5,"") -> 23.635804 | W5: =IFERROR(D5/P5,0) -> 0.21784722 | X5: =IFERROR(E5/P5,0) -> 0.081759259 | Y5: =IFERROR(1-((D5+E5)/P5),0) -> 0.70039352
